Workbook

Sheet README
A1: Excel Practice Pack — Data Analyst Skills
A2: A corporate-style sales dataset with hands-on exercises for formulas, pivot tables, data cleaning, and dashboards.
A4: How this workbook is organized
A5: Sheet | B5: What to do there
A6: Raw_Data | B6: A messy 330-row corporate sales dataset — inconsistent casing, extra spaces, mixed date formats, blanks, duplicates, and text-formatted numbers. Practice cleaning it here.
A7: Cleaning_Tasks | B7: Step-by-step data cleaning checklist referencing Raw_Data. Work directly in Raw_Data or copy it to a new sheet first.
A8: Lookup_Tables | B8: Reference tables (Sales Rep directory, Product catalog) used for VLOOKUP / XLOOKUP / INDEX-MATCH practice.
A9: Formulas_Practice | B9: A trimmed, clean order table with blank columns for you to fill in using formulas (lookups, IF logic, calculations).
A10: Answer_Key | B10: Worked formulas for Formulas_Practice — check your work, don't peek early!
A11: PivotTable_Practice | B11: A clean, ready-to-use dataset plus 5 pivot table tasks that mirror real reporting requests.
A12: Dashboard_Practice | B12: Same clean dataset plus instructions to build a 1-page mini dashboard with 3 charts.
A14: Suggested order
A15: 1. Clean Raw_Data using the Cleaning_Tasks checklist (this is the messiest, most realistic part).
A16: 2. Practice lookups and logic formulas in Formulas_Practice, then self-check with Answer_Key.
A17: 3. Build the requested pivot tables in PivotTable_Practice.
A18: 4. Turn your pivot output into a small dashboard in Dashboard_Practice.

Sheet Table1
A1: Order ID | B1: Order Date | C1: Customer Name | D1: Region | E1: Product Category | F1: Product Name | G1: Qty | H1: unit Price | I1: Discount | J1: Sales Rep new | K1: Payment Method | L1: Order Status
A2: 10261 | B2: 45389 | C2: Vivek Rao | D2: North | E2: Electronics | F2: Mechanical Keyboard | G2: 1 | H2: 2999 | I2: 0.05 | J2: James Fernandes | K2: Cheque | L2: Completed
A3: 10205 | B3: 45316 | C3: Pooja Menon | D3: West | E3: Electronics | F3: Portable SSD 1TB | G3: 2 | H3: 6499 | I3: 0.1 | J3: Farah Khan | K3: Bank Transfer | L3: Pending
A4: 10175 | B4: 45336 | C4: Kavya Reddy | D4: West | E4: Electronics | F4: Wireless Mouse | G4: 4 | H4: 799 | I4: 0.05 | J4: Farah Khan | K4: Credit Card | L4: Cancelled
A5: 10111 | B5: 45482 | C5: Arjun Patel | D5: South | E5: Office Supplies | F5: Sticky Notes Pack | G5: 4 | H5: 149 | I5: 0.1 | J5: Meera Krishnan | K5: Credit Card | L5: Completed
A6: 10071 | B6: 45734 | C6: Global Retail Corp | D6: Central | E6: Software | F6: CRM Subscription | G6: 5 | H6: 3999 | I6: 0.05 | J6: Farah Khan | K6: Cash | L6: Cancelled
A7: 10128 | B7: 45344 | C7: Karan Malhotra | D7: East | E7: Office Supplies | F7: File Folders Box | G7: 1 | H7: 429 | I7: 0.05 | J7: Meera Krishnan | K7: Credit Card | L7: Completed
A8: 10308 | B8: 45349 | C8: Divya Pillai | D8: East | E8: Office Supplies | F8: Stapler Set | G8: 3 | H8: 349 | I8: 0.1 | J8: Meera Krishnan | K8: Bank Transfer | L8: Cancelled
A9: 10265 | B9: 45667 | C9: Arjun Patel | D9: Central | E9: Furniture | F9: Office Sofa | G9: 3 | H9: 18999 | I9: 0 | J9: James Fernandes | K9: Cash | L9: Completed
A10: 10198 | B10: 45645 | C10: Horizon Systems | D10: East | E10: Furniture | F10: Standing Desk | G10: 4 | H10: 15999 | I10: 0.05 | J10: Meera Krishnan | K10: Credit Card | L10: Pending
A11: 10309 | B11: 45686 | C11: Manish Joshi | D11: North | E11: Electronics | F11: Webcam HD | G11: 2 | H11: 1799 | I11: 0.05 | J11: James Fernandes | K11: UPI | L11: Completed
A12: 10145 | B12: 45545 | C12: Siddharth Gupta | D12: West | E12: Electronics | F12: USB-C Hub | G12: 5 | H12: 1499 | I12: 0 | J12: Meera Krishnan | K12: UPI | L12: Completed
A13: 10158 | B13: 45753 | C13: Pooja Menon | D13: West | E13: Furniture | F13: Filing Cabinet | G13: 4 | H13: 6999 | I13: 0.1 | J13: Not Assigned | K13: Cash | L13: Pending
A14: 10073 | C14: Arjun Patel | D14: Central | E14: Furniture | F14: Storage Cabinet | G14: 4 | H14: 5499 | I14: 0.05 | J14: James Fernandes | K14: Cash | L14: Completed
A15: 10155 | C15: Amitabh Sinha | D15: East | E15: Furniture | F15: Standing Desk | G15: 0 | H15: 15999 | I15: 0.05 | J15: Farah Khan | K15: Bank Transfer | L15: Completed
A16: 10279 | B16: 45347 | C16: Nikhil Chawla | D16: Central | E16: Software | F16: Design Suite License | G16: 6 | H16: 5499 | I16: 0.1 | J16: Farah Khan | K16: Cash | L16: Completed
A17: 10219 | B17: 45627 | C17: Ananya Iyer | D17: North | E17: Electronics | F17: Mechanical Keyboard | G17: 4 | H17: 2999 | I17: 0.1 | J17: James Fernandes | K17: Cash | L17: Cancelled
A18: 10152 | B18: 45684 | C18: Riya Desai | D18: South | E18: Electronics | F18: Mechanical Keyboard | G18: 4 | H18: 2999 | I18: 0.1 | J18: Reetu Sharma | K18: Credit Card | L18: Cancelled
A19: 10041 | B19: 45328 | C19: Sana Sheikh | D19: West | E19: Furniture | F19: Filing Cabinet | G19: 6 | H19: 6999 | I19: 0 | J19: Reetu Sharma | K19: Credit Card | L19: Completed
A20: 10191 | B20: 45901 | C20: Ishita Sharma | D20: West | E20: Software | F20: VPN License | G20: 4 | H20: 599 | I20: 0.05 | J20: Alok Bansal | K20: Bank Transfer | L20: Not Updated
A21: 10181 | B21: 45642 | C21: Neha Verma | D21: East | E21: Electronics | F21: Portable SSD 1TB | G21: 5 | H21: 6499 | I21: 0.1 | J21: Meera Krishnan | K21: UPI | L21: Cancelled
A22: 10238 | B22: 45575 | C22: Priya Nair | D22: East | E22: Furniture | F22: Ergonomic Chair | G22: 4 | H22: 8999 | I22: 0 | J22: James Fernandes | K22: Cheque | L22: Pending
A23: 10217 | C23: Ishita Sharma | D23: Central | E23: Office Supplies | F23: File Folders Box | G23: 2 | H23: 429 | I23: 0.1 | J23: Meera Krishnan | K23: Cash | L23: Completed
A24: 10085 | B24: 45605 | C24: Ishita Sharma | D24: West | E24: Furniture | F24: Desk Lamp | G24: 4 | H24: 1299 | I24: 0.1 | J24: Alok Bansal | K24: Cash | L24: Completed
A25: 10053 | B25: 45643 | C25: Apex Manufacturing | D25: East | E25: Furniture | F25: Conference Table | G25: 6 | H25: 24999 | I25: 0 | J25: Reetu Sharma | K25: Cash | L25: Pending
A26: 10022 | B26: 45665 | C26: Silverline Logistics | D26: North | E26: Furniture | F26: Ergonomic Chair | G26: 3 | H26: 8999 | I26: 0.05 | J26: Meera Krishnan | K26: Cheque | L26: Completed
A27: 10018 | C27: Tanvi Bhatt | D27: East | E27: Office Supplies | F27: Desk Organizer | G27: 3 | H27: 599 | I27: 0.05 | J27: Farah Khan | K27: UPI | L27: Not Updated
A28: 10089 | C28: Technova Solutions | D28: North | E28: Software | F28: Project Mgmt Tool | G28: 4 | H28: 2499 | I28: 0 | J28: James Fernandes | K28: Bank Transfer | L28: Cancelled
A29: 10277 | B29: 45423 | C29: Tanvi Bhatt | D29: South | E29: Office Supplies | F29: Whiteboard Markers | G29: 6 | H29: 199 | I29: 0 | J29: Reetu Sharma | K29: Bank Transfer | L29: Pending
A30: 10165 | B30: 45331 | C30: Sana Sheikh | D30: Central | E30: Office Supplies | F30: A4 Paper Ream | G30: 6 | H30: 249 | I30: 0.1 | J30: Farah Khan | K30: Bank Transfer | L30: Completed
A31: 10300 | C31: Technova Solutions | D31: Central | E31: Software | F31: Cloud Storage Plan | G31: 2 | H31: 799 | I31: 0.1 | J31: Reetu Sharma | K31: Bank Transfer | L31: Pending
A32: 10014 | C32: Riya Desai | D32: North | E32: Office Supplies | F32: File Folders Box | G32: 4 | H32: 429 | I32: 0.05 | J32: James Fernandes | K32: Cash | L32: Completed
A33: 10133 | B33: 45651 | C33: Silverline Logistics | D33: West | E33: Software | F33: Design Suite License | G33: 6 | H33: 5499 | I33: 0.1 | J33: Farah Khan | K33: Cash | L33: Pending
A34: 10169 | B34: 45761 | C34: Karan Malhotra | D34: East | E34: Office Supplies | F34: Sticky Notes Pack | G34: 3 | H34: 149 | I34: 0.1 | J34: James Fernandes | K34: Cash | L34: Completed
A35: 10245 | B35: 45507 | C35: Global Retail Corp | D35: East | E35: Software | F35: Design Suite License | G35: 2 | H35: 5499 | I35: 0.05 | J35: Not Assigned | K35: UPI | L35: Cancelled
A36: 10197 | B36: 45351 | C36: Neha Verma | D36: South | E36: Electronics | F36: USB-C Hub | G36: 3 | H36: 1499 | I36: 0.1 | J36: Reetu Sharma | K36: UPI | L36: Cancelled
A37: 10140 | B37: 45501 | C37: Technova Solutions | D37: West | E37: Furniture | F37: Ergonomic Chair | G37: 4 | H37: 8999 | I37: 0.05 | J37: James Fernandes | K37: Bank Transfer | L37: Not Updated
A38: 10094 | B38: 45689 | C38: Aditya Kapoor | D38: West | E38: Electronics | F38: 27in Monitor | G38: 2 | H38: 12999 | I38: 0 | J38: Alok Bansal | K38: UPI | L38: Completed
A39: 10315 | B39: 45566 | C39: Tanvi Bhatt | D39: East | E39: Electronics | F39: Portable SSD 1TB | G39: 0 | H39: 6499 | I39: 0.05 | J39: Reetu Sharma | K39: Cheque | L39: Cancelled
A40: 10098 | C40: Rahul Saxena | D40: East | E40: Electronics | F40: Noise Cancelling Headphones | G40: 3 | H40: 5999 | I40: 0 | J40: Meera Krishnan | K40: Cash | L40: Pending
...

Sheet Raw_Data
A1: Order ID | B1: Order Date | C1: Customer Name | D1: Region | E1: Product Category | F1: Product Name | G1: Qty | H1: unit Price | I1: Discount | J1: Line Total | K1: Sales Representative | L1: Payment Method | M1: Order Status
A2: 10261 | B2: 45389 | C2: Vivek Rao | D2: North | E2: Electronics | F2: Mechanical Keyboard | G2: 1 | H2: 2999 | I2: 0.05 | J2: 2849.05 | K2: James Fernandes | L2: Cheque | M2: Completed
A3: 10205 | B3: 45316 | C3: Pooja Menon | D3: West | E3: Electronics | F3: Portable SSD 1TB | G3: 2 | H3: 6499 | I3: 0.1 | J3: 11698.2 | K3: Farah Khan | L3: Bank Transfer | M3: Pending
A4: 10175 | B4: 45336 | C4: Kavya Reddy | D4: West | E4: Electronics | F4: Wireless Mouse | G4: 4 | H4: 799 | I4: 0.05 | J4: 3036.2 | K4: Farah Khan | L4: Credit Card | M4: Cancelled
A5: 10111 | B5: 45482 | C5: Arjun Patel | D5: South | E5: Office Supplies | F5: Sticky Notes Pack | G5: 4 | H5: 149 | I5: 0.1 | J5: 536.4 | K5: Meera Krishnan | L5: Credit Card | M5: Completed
A6: 10071 | B6: 45734 | C6: Global Retail Corp | D6: Central | E6: Software | F6: CRM Subscription | G6: 5 | H6: 3999 | I6: 0.05 | J6: 18995.25 | K6: Farah Khan | L6: Cash | M6: Cancelled
A7: 10128 | B7: 45344 | C7: Karan Malhotra | D7: East | E7: Office Supplies | F7: File Folders Box | G7: 1 | H7: 429 | I7: 0.05 | J7: 407.55 | K7: Meera Krishnan | L7: Credit Card | M7: Completed
A8: 10308 | B8: 45349 | C8: Divya Pillai | D8: East | E8: Office Supplies | F8: Stapler Set | G8: 3 | H8: 349 | I8: 0.1 | J8: 942.3 | K8: Meera Krishnan | L8: Bank Transfer | M8: Cancelled
A9: 10265 | B9: 45667 | C9: Arjun Patel | D9: Central | E9: Furniture | F9: Office Sofa | G9: 3 | H9: 18999 | I9: 0 | J9: 56997 | K9: James Fernandes | L9: Cash | M9: Completed
A10: 10198 | B10: 45645 | C10: Horizon Systems | D10: East | E10: Furniture | F10: Standing Desk | G10: 4 | H10: 15999 | I10: 0.05 | J10: 60796.2 | K10: Meera Krishnan | L10: Credit Card | M10: Pending
A11: 10309 | B11: 45686 | C11: Manish Joshi | D11: North | E11: Electronics | F11: Webcam HD | G11: 2 | H11: 1799 | I11: 0.05 | J11: 3418.1 | K11: James Fernandes | L11: UPI | M11: Completed
A12: 10145 | B12: 45545 | C12: Siddharth Gupta | D12: West | E12: Electronics | F12: USB-C Hub | G12: 5 | H12: 1499 | I12: 0 | J12: 7495 | K12: Meera Krishnan | L12: UPI | M12: Completed
A13: 10158 | B13: 45753 | C13: Pooja Menon | D13: West | E13: Furniture | F13: Filing Cabinet | G13: 4 | H13: 6999 | I13: 0.1 | J13: 25196.4 | K13: Not Assigned | L13: Cash | M13: Pending
... A153: 10035 | B153: 45335 | C153: Ananya Iyer | D153: East | E153: Furniture | F153: Office Sofa | G153: 3 | H153: 18999 | I153: 0 | J153: 56997 | K153: Farah Khan | L153: Cheque | M153: Completed
A154: 10189 | B154: 45747 | C154: Vivek Rao | D154: North | E154: Furniture | F154: Storage Cabinet | G154: Invalid | H154: 5499 | I154: 0.05 | J154: No Qty | K154: Alok Bansal | L154: Bank Transfer | M154: Pending
A155: 10105 | B155: 45770 | C155: Tanvi Bhatt | D155: North | E155: Furniture | F155: Storage Cabinet | G155: 0 | H155: 5499 | I155: 0.1 | J155: 0 | K155: James Fernandes | L155: Cash | M155: Completed
A156: 10224 | B156: 45652 | C156: Rahul Saxena | D156: West | E156: Office Supplies | F156: Ink Cartridge | G156: 1 | H156: 899 | I156: 0 | J156: 899 | K156: Alok Bansal | L156: UPI | M156: Completed
A157: 10143 | B157: 45441 | C157: Kavya Reddy | D157: North | E157: Office Supplies | F157: Whiteboard Markers | G157: 3 | H157: 199 | I157: 0.1 | J157: 537.3 | K157: Farah Khan | L157: Bank Transfer | M157: Cancelled
A158: 10023 | B158: 45660 | C158: Kavya Reddy | D158: West | E158: Office Supplies | F158: Ink Cartridge | G158: 3 | H158: 899 | I158: 0 | J158: 2697 | K158: Reetu Sharma | L158: Cheque | M158: Pending
A159: 10062 | B159: 45350 | C159: Horizon Systems | D159: Central | E159: Furniture | F159: Desk Lamp | G159: 5 | H159: 1299 | I159: 0.1 | J159: 5845.5 | K159: Farah Khan | L159: Cheque | M159: Completed
A160: 10127 | B160: 45513 | C160: Priya Nair | D160: North | E160: Software | F160: Cloud Storage Plan | G160: 4 | H160: 799 | I160: 0.05 | J160: 3036.2 | K160: Meera Krishnan | L160: Credit Card | M160: Completed
A161: 10116 | B161: 45639 | C161: Riya Desai | D161: East | E161: Office Supplies | F161: File Folders Box | G161: 5 | H161: 429 | I161: 0.1 | J161: 1930.5 | K161: Meera Krishnan | L161: UPI | M161: Completed
A162: 10310 | B162: 45534 | C162: Siddharth Gupta | D162: West | E162: Software | F162: CRM Subscription | G162: 5 | H162: 3999 | I162: 0.05 | J162: 18995.25 | K162: Meera Krishnan | L162: Cash | M162: Cancelled
A163: 10101 | B163: 45738 | C163: Horizon Systems | D163: South | E163: Furniture | F163: Desk Lamp | G163: 4 | H163: 1299 | I163: 0.05 | J163: 4936.2 | K163: Alok Bansal | L163: Cash | M163: Completed
A164: 10136 | B164: 45381 | C164: Pooja Menon | D164: East | E164: Electronics | F164: Wireless Mouse | G164: 2 | H164: 799 | I164: 0.1 | J164: 1438.2 | K164: Reetu Sharma | L164: Bank Transfer | M164: Pending
A165: 10109 | B165: 45645 | C165: Neha Verma | D165: East | E165: Electronics | F165: Portable SSD 1TB | G165: 5 | H165: 6499 | I165: 0.05 | J165: 30870.25 | K165: James Fernandes | L165: Bank Transfer | M165: Completed
A166: 10216 | B166: 45767 | C166: Rahul Saxena | D166: Central | E166: Electronics | F166: Wireless Mouse | G166: 5 | H166: 799 | I166: 0.05 | J166: 3795.25 | K166: Reetu Sharma | L166: Cheque | M166: Completed
... A298: 10255 | B298: 45371 | C298: Ishita Sharma | D298: South | E298: Electronics | F298: Noise Cancelling Headphones | G298: 5 | H298: 5999 | I298: 0.1 | J298: 26995.5 | K298: Reetu Sharma | L298: Credit Card | M298: Completed
A299: 10093 | B299: 45505 | C299: Divya Pillai | D299: North | E299: Furniture | F299: Ergonomic Chair | G299: Invalid | H299: 8999 | I299: 0.1 | J299: No Qty | K299: Reetu Sharma | L299: UPI | M299: Completed
A300: 10305 | B300: 45480 | C300: Neha Verma | D300: West | E300: Office Supplies | F300: Desk Organizer | G300: 1 | H300: 599 | I300: 0.1 | J300: 539.1 | K300: Farah Khan | L300: Cheque | M300: Cancelled
A301: 10021 | B301: 45406 | C301: Rohan Mehta | D301: North | E301: Electronics | F301: Noise Cancelling Headphones | G301: 4 | H301: 5999 | I301: 0 | J301: 23996 | K301: Alok Bansal | L301: UPI | M301: Cancelled
A302: 10090 | B302: 45531 | C302: Silverline Logistics | D302: South | E302: Office Supplies | F302: Stapler Set | G302: 4 | H302: 349 | I302: 0.05 | J302: 1326.2 | K302: James Fernandes | L302: Cash | M302: Completed
A303: 10123 | B303: 45356 | C303: Vivek Rao | D303: Central | E303: Furniture | F303: Ergonomic Chair | G303: 2 | H303: 8999 | I303: 0.05 | J303: 17098.1 | K303: Alok Bansal | L303: Cheque | M303: Completed
A304: 10210 | B304: 45571 | C304: Sunrise Traders | D304: Central | E304: Furniture | F304: Filing Cabinet | G304: 6 | H304: 6999 | I304: 0.1 | J304: 37794.6 | K304: Alok Bansal | L304: Cash | M304: Pending
A305: 10230 | B305: 45342 | C305: Riya Desai | D305: West | E305: Software | F305: Project Mgmt Tool | G305: 6 | H305: 2499 | I305: 0.1 | J305: 13494.6 | K305: Alok Bansal | L305: Cheque | M305: Completed
A306: 10267 | B306: 45440 | C306: Silverline Logistics | D306: North | E306: Office Supplies | F306: Sticky Notes Pack | G306: 5 | H306: 149 | I306: 0.15 | J306: 633.25 | K306: Alok Bansal | L306: Cheque | M306: Completed
A307: 10139 | B307: 45617 | C307: Pooja Menon | D307: Central | E307: Furniture | F307: Bookshelf | G307: 2 | H307: 4999 | I307: 0.05 | J307: 9498.1 | K307: Alok Bansal | L307: Cheque | M307: Cancelled
A308: 10074 | B308: 45463 | C308: Arjun Patel | D308: West | E308: Furniture | F308: Conference Table | G308: 6 | H308: 24999 | I308: 0.1 | J308: 134994.6 | K308: Alok Bansal | L308: Bank Transfer | M308: Completed
A309: 10106 | B309: 45387 | C309: Sunrise Traders | D309: West | E309: Electronics | F309: 27in Monitor | G309: 1 | H309: 12999 | I309: 0.05 | J309: 12349.05 | K309: Not Assigned | L309: UPI | M309: Completed
A310: 10065 | B310: 45737 | C310: Karan Malhotra | D310: North | E310: Electronics | F310: Mechanical Keyboard | G310: 3 | H310: 2999 | I310: 0 | J310: 8997 | K310: James Fernandes | L310: Cash | M310: Completed
...

Sheet Cleaning_Tasks
A1: Data Cleaning Checklist
A2: All tasks refer to the Raw_Data sheet (330 rows, 12 columns). Try each with formulas or built-in Excel tools.
A4: ☐ 1. Remove exact duplicate rows (Data > Remove Duplicates). How many duplicates were removed?
A5: ☐ 2. Delete fully blank rows.
A6: ☐ 3. Trim leading/trailing spaces from Customer Name, Region, and Product Category (TRIM function).
A7: ☐ 4. Standardize Region values to exactly: North, South, East, West, Central (fix typos like 'Nrth', 'Est', 'Wst' and inconsistent casing — try PROPER + nested SUBSTITUTE, or Find & Replace).
A8: ☐ 5. Standardize Product Category casing using PROPER(), then fix the 'Electronic' → 'Electronics' typo.
A9: ☐ 6. Convert Order Date into one consistent date format (some rows are DD/MM/YYYY text, some 'Mon DD, YYYY' text, some already ISO dates). Try DATEVALUE for text dates.
A10: ☐ 7. Clean Unit Price: some values are stored as text with a '$' prefix (e.g. "$18999"). Convert all to numeric.
A11: ☐ 8. Fill or flag blank Quantity and blank Sales Rep cells — decide whether to impute, flag, or drop them.
A12: ☐ 9. Standardize Sales Rep names to one format (e.g. 'Reetu Sharma' instead of 'R. Sharma' / 'reetu sharma'). Try a lookup against Lookup_Tables!SalesReps.
A13: ☐ 10. Flag invalid rows where Quantity is 0 or negative — these are likely data-entry errors, not real orders.
A14: ☐ 11. Add a calculated 'Line Total' column: Quantity × Unit Price × (1 − Discount), handling blank Discount as 0.

Sheet Lookup_Tables
A1: Reference Tables
A3: Sales Rep Directory
A4: Rep ID | B4: Full Name | C4: Department | D4: Region Covered | E4: Target ($)
A5: SR01 | B5: Reetu Sharma | C5: Enterprise Sales | D5: North | E5: 1500000
A6: SR02 | B6: James Fernandes | C6: SMB Sales | D6: West | E6: 1200000
A7: SR03 | B7: Meera Krishnan | C7: Enterprise Sales | D7: South | E7: 1600000
A8: SR04 | B8: Alok Bansal | C8: SMB Sales | D8: Central | E8: 1100000
A9: SR05 | B9: Farah Khan | C9: Key Accounts | D9: East | E9: 1750000
A12: Product Catalog
A13: Product Name | B13: Category | C13: List Price | D13: Reorder Level
A14: Wireless Mouse | B14: Electronics | C14: 799 | D14: 50
A15: USB-C Hub | B15: Electronics | C15: 1499 | D15: 30
A16: 27in Monitor | B16: Electronics | C16: 12999 | D16: 15
A17: Laptop Stand | B17: Electronics | C17: 1199 | D17: 40
A18: Mechanical Keyboard | B18: Electronics | C18: 2999 | D18: 25
A19: Webcam HD | B19: Electronics | C19: 1799 | D19: 20
A20: Noise Cancelling Headphones | B20: Electronics | C20: 5999 | D20: 15
A21: Portable SSD 1TB | B21: Electronics | C21: 6499 | D21: 20
A22: A4 Paper Ream | B22: Office Supplies | C22: 249 | D22: 200
A23: Stapler Set | B23: Office Supplies | C23: 349 | D23: 80
A24: Sticky Notes Pack | B24: Office Supplies | C24: 149 | D24: 150
A25: Whiteboard Markers | B25: Office Supplies | C25: 199 | D25: 100
... A43: VPN License | B43: Software | C43: 599 | D43: 999

Sheet Formulas_Practice
A1: Order ID | B1: Order Date | C1: Customer Name | D1: Region | E1: Product Category | F1: Product Name | G1: Qty | H1: unit Price | I1: Discount | J1: Sales Rep new | K1: Payment Method | L1: Order Status
A2: Fill in the yellow columns using formulas. Lookup source: Lookup_Tables sheet. Check yourself in Answer_Key.
A4: Order ID | B4: Rep ID | C4: Rep Full Name (VLOOKUP/XLOOKUP) | D4: Product Name | E4: Category (INDEX-MATCH) | F4: List Price (XLOOKUP) | G4: Quantity | H4: Line Total = Qty×Price | I4: Discount Tier (nested IF) | J4: Order Value Band (IF) | K4: Department | L4: Region
A5: 5002 | B5: SR03 | C5: =VLOOKUP(B5,Lookup_Tables!$A$4:$B$9,2,FALSE) -> Meera Krishnan | D5: Mechanical Keyboard | E5: =INDEX(Lookup_Tables!$B$14:$B$43,MATCH(Formulas_Practice!D5,Lookup_Tables!$A$14:$A$43,0)) -> Electronics | F5: =VLOOKUP(D5,Lookup_Tables!$A$13:$C$43,3,FALSE) -> 2999 | G5: 7 | H5: =G5*F5 -> 20993 | I5: {=_xlfn.IFS(G5<5,"No Discount",G5<10,"5-10 Tier Discount",G5>=10,"10+ Tier Discount")} -> 5-10 Tier Discount | J5: =IF(H5>50000,"High",IF(H5<15000,"Medium","Standard")) -> Standard | K5: =VLOOKUP(B5,Lookup_Tables!$A$4:$E$9,3,FALSE) -> Enterprise Sales | L5: =INDEX(Lookup_Tables!$D$4:$D$9,MATCH(Formulas_Practice!K5,Lookup_Tables!$C$4:$C$9,0)) -> North
A6: 5003 | B6: SR01 | C6: =VLOOKUP(B6,Lookup_Tables!$A$4:$B$9,2,FALSE) -> Reetu Sharma | D6: 27in Monitor | E6: =INDEX(Lookup_Tables!$B$14:$B$43,MATCH(Formulas_Practice!D6,Lookup_Tables!$A$14:$A$43,0)) -> Electronics | F6: =VLOOKUP(D6,Lookup_Tables!$A$13:$C$43,3,FALSE) -> 12999 | G6: 9 | H6: =G6*F6 -> 116991 | I6: {=_xlfn.IFS(G6<5,"No Discount",G6<10,"5-10 Tier Discount",G6>=10,"10+ Tier Discount")} -> 5-10 Tier Discount | J6: =IF(H6>50000,"High",IF(H6<15000,"Medium","Standard")) -> High | K6: =VLOOKUP(B6,Lookup_Tables!$A$4:$E$9,3,FALSE) -> Enterprise Sales | L6: =INDEX(Lookup_Tables!$D$4:$D$9,MATCH(Formulas_Practice!K6,Lookup_Tables!$C$4:$C$9,0)) -> North
A7: 5004 | B7: SR01 | C7: =VLOOKUP(B7,Lookup_Tables!$A$4:$B$9,2,FALSE) -> Reetu Sharma | D7: Whiteboard Markers | E7: =INDEX(Lookup_Tables!$B$14:$B$43,MATCH(Formulas_Practice!D7,Lookup_Tables!$A$14:$A$43,0)) -> Office Supplies | F7: =VLOOKUP(D7,Lookup_Tables!$A$13:$C$43,3,FALSE) -> 199 | G7: 10 | H7: =G7*F7 -> 1990 | I7: {=_xlfn.IFS(G7<5,"No Discount",G7<10,"5-10 Tier Discount",G7>=10,"10+ Tier Discount")} -> 10+ Tier Discount | J7: =IF(H7>50000,"High",IF(H7<15000,"Medium","Standard")) -> Medium | K7: =VLOOKUP(B7,Lookup_Tables!$A$4:$E$9,3,FALSE) -> Enterprise Sales | L7: =INDEX(Lookup_Tables!$D$4:$D$9,MATCH(Formulas_Practice!K7,Lookup_Tables!$C$4:$C$9,0)) -> North
A8: 5005 | B8: SR01 | C8: =VLOOKUP(B8,Lookup_Tables!$A$4:$B$9,2,FALSE) -> Reetu Sharma | D8: VPN License | E8: =INDEX(Lookup_Tables!$B$14:$B$43,MATCH(Formulas_Practice!D8,Lookup_Tables!$A$14:$A$43,0)) -> Software | F8: =VLOOKUP(D8,Lookup_Tables!$A$13:$C$43,3,FALSE) -> 599 | G8: 9 | H8: =G8*F8 -> 5391 | I8: {=_xlfn.IFS(G8<5,"No Discount",G8<10,"5-10 Tier Discount",G8>=10,"10+ Tier Discount")} -> 5-10 Tier Discount | J8: =IF(H8>50000,"High",IF(H8<15000,"Medium","Standard")) -> Medium | K8: =VLOOKUP(B8,Lookup_Tables!$A$4:$E$9,3,FALSE) -> Enterprise Sales | L8: =INDEX(Lookup_Tables!$D$4:$D$9,MATCH(Formulas_Practice!K8,Lookup_Tables!$C$4:$C$9,0)) -> North
A9: 5006 | B9: SR02 | C9: =VLOOKUP(B9,Lookup_Tables!$A$4:$B$9,2,FALSE) -> James Fernandes | D9: USB-C Hub | E9: =INDEX(Lookup_Tables!$B$14:$B$43,MATCH(Formulas_Practice!D9,Lookup_Tables!$A$14:$A$43,0)) -> Electronics | F9: =VLOOKUP(D9,Lookup_Tables!$A$13:$C$43,3,FALSE) -> 1499 | G9: 2 | H9: =G9*F9 -> 2998 | I9: {=_xlfn.IFS(G9<5,"No Discount",G9<10,"5-10 Tier Discount",G9>=10,"10+ Tier Discount")} -> No Discount | J9: =IF(H9>50000,"High",IF(H9<15000,"Medium","Standard")) -> Medium | K9: =VLOOKUP(B9,Lookup_Tables!$A$4:$E$9,3,FALSE) -> SMB Sales | L9: =INDEX(Lookup_Tables!$D$4:$D$9,MATCH(Formulas_Practice!K9,Lookup_Tables!$C$4:$C$9,0)) -> West
A10: 5007 | B10: SR04 | C10: =VLOOKUP(B10,Lookup_Tables!$A$4:$B$9,2,FALSE) -> Alok Bansal | D10: Ink Cartridge | E10: =INDEX(Lookup_Tables!$B$14:$B$43,MATCH(Formulas_Practice!D10,Lookup_Tables!$A$14:$A$43,0)) -> Office Supplies | F10: =VLOOKUP(D10,Lookup_Tables!$A$13:$C$43,3,FALSE) -> 899 | G10: 2 | H10: =G10*F10 -> 1798 | I10: {=_xlfn.IFS(G10<5,"No Discount",G10<10,"5-10 Tier Discount",G10>=10,"10+ Tier Discount")} -> No Discount | J10: =IF(H10>50000,"High",IF(H10<15000,"Medium","Standard")) -> Medium | K10: =VLOOKUP(B10,Lookup_Tables!$A$4:$E$9,3,FALSE) -> SMB Sales | L10: =INDEX(Lookup_Tables!$D$4:$D$9,MATCH(Formulas_Practice!K10,Lookup_Tables!$C$4:$C$9,0)) -> West
A11: 5008 | B11: SR02 | C11: =VLOOKUP(B11,Lookup_Tables!$A$4:$B$9,2,FALSE) -> James Fernandes | D11: 27in Monitor | E11: =INDEX(Lookup_Tables!$B$14:$B$43,MATCH(Formulas_Practice!D11,Lookup_Tables!$A$14:$A$43,0)) -> Electronics | F11: =VLOOKUP(D11,Lookup_Tables!$A$13:$C$43,3,FALSE) -> 12999 | G11: 9 | H11: =G11*F11 -> 116991 | I11: {=_xlfn.IFS(G11<5,"No Discount",G11<10,"5-10 Tier Discount",G11>=10,"10+ Tier Discount")} -> 5-10 Tier Discount | J11: =IF(H11>50000,"High",IF(H11<15000,"Medium","Standard")) -> High | K11: =VLOOKUP(B11,Lookup_Tables!$A$4:$E$9,3,FALSE) -> SMB Sales | L11: =INDEX(Lookup_Tables!$D$4:$D$9,MATCH(Formulas_Practice!K11,Lookup_Tables!$C$4:$C$9,0)) -> West
A12: 5009 | B12: SR04 | C12: =VLOOKUP(B12,Lookup_Tables!$A$4:$B$9,2,FALSE) -> Alok Bansal | D12: USB-C Hub | E12: =INDEX(Lookup_Tables!$B$14:$B$43,MATCH(Formulas_Practice!D12,Lookup_Tables!$A$14:$A$43,0)) -> Electronics | F12: =VLOOKUP(D12,Lookup_Tables!$A$13:$C$43,3,FALSE) -> 1499 | G12: 10 | H12: =G12*F12 -> 14990 | I12: {=_xlfn.IFS(G12<5,"No Discount",G12<10,"5-10 Tier Discount",G12>=10,"10+ Tier Discount")} -> 10+ Tier Discount | J12: =IF(H12>50000,"High",IF(H12<15000,"Medium","Standard")) -> Medium | K12: =VLOOKUP(B12,Lookup_Tables!$A$4:$E$9,3,FALSE) -> SMB Sales | L12: =INDEX(Lookup_Tables!$D$4:$D$9,MATCH(Formulas_Practice!K12,Lookup_Tables!$C$4:$C$9,0)) -> West
A13: 5010 | B13: SR01 | C13: =VLOOKUP(B13,Lookup_Tables!$A$4:$B$9,2,FALSE) -> Reetu Sharma | D13: Portable SSD 1TB | E13: =INDEX(Lookup_Tables!$B$14:$B$43,MATCH(Formulas_Practice!D13,Lookup_Tables!$A$14:$A$43,0)) -> Electronics | F13: =VLOOKUP(D13,Lookup_Tables!$A$13:$C$43,3,FALSE) -> 6499 | G13: 11 | H13: =G13*F13 -> 71489 | I13: {=_xlfn.IFS(G13<5,"No Discount",G13<10,"5-10 Tier Discount",G13>=10,"10+ Tier Discount")} -> 10+ Tier Discount | J13: =IF(H13>50000,"High",IF(H13<15000,"Medium","Standard")) -> High | K13: =VLOOKUP(B13,Lookup_Tables!$A$4:$E$9,3,FALSE) -> Enterprise Sales | L13: =INDEX(Lookup_Tables!$D$4:$D$9,MATCH(Formulas_Practice!K13,Lookup_Tables!$C$4:$C$9,0)) -> North
A14: 5011 | B14: SR05 | C14: =VLOOKUP(B14,Lookup_Tables!$A$4:$B$9,2,FALSE) -> Farah Khan | D14: USB-C Hub | E14: =INDEX(Lookup_Tables!$B$14:$B$43,MATCH(Formulas_Practice!D14,Lookup_Tables!$A$14:$A$43,0)) -> Electronics | F14: =VLOOKUP(D14,Lookup_Tables!$A$13:$C$43,3,FALSE) -> 1499 | G14: 10 | H14: =G14*F14 -> 14990 | I14: {=_xlfn.IFS(G14<5,"No Discount",G14<10,"5-10 Tier Discount",G14>=10,"10+ Tier Discount")} -> 10+ Tier Discount | J14: =IF(H14>50000,"High",IF(H14<15000,"Medium","Standard")) -> Medium | K14: =VLOOKUP(B14,Lookup_Tables!$A$4:$E$9,3,FALSE) -> Key Accounts | L14: =INDEX(Lookup_Tables!$D$4:$D$9,MATCH(Formulas_Practice!K14,Lookup_Tables!$C$4:$C$9,0)) -> East
A15: 5012 | B15: SR05 | C15: =VLOOKUP(B15,Lookup_Tables!$A$4:$B$9,2,FALSE) -> Farah Khan | D15: Desk Organizer | E15: =INDEX(Lookup_Tables!$B$14:$B$43,MATCH(Formulas_Practice!D15,Lookup_Tables!$A$14:$A$43,0)) -> Office Supplies | F15: =VLOOKUP(D15,Lookup_Tables!$A$13:$C$43,3,FALSE) -> 599 | G15: 1 | H15: =G15*F15 -> 599 | I15: {=_xlfn.IFS(G15<5,"No Discount",G15<10,"5-10 Tier Discount",G15>=10,"10+ Tier Discount")} -> No Discount | J15: =IF(H15>50000,"High",IF(H15<15000,"Medium","Standard")) -> Medium | K15: =VLOOKUP(B15,Lookup_Tables!$A$4:$E$9,3,FALSE) -> Key Accounts | L15: =INDEX(Lookup_Tables!$D$4:$D$9,MATCH(Formulas_Practice!K15,Lookup_Tables!$C$4:$C$9,0)) -> East
A16: 5013 | B16: SR02 | C16: =VLOOKUP(B16,Lookup_Tables!$A$4:$B$9,2,FALSE) -> James Fernandes | D16: USB-C Hub | E16: =INDEX(Lookup_Tables!$B$14:$B$43,MATCH(Formulas_Practice!D16,Lookup_Tables!$A$14:$A$43,0)) -> Electronics | F16: =VLOOKUP(D16,Lookup_Tables!$A$13:$C$43,3,FALSE) -> 1499 | G16: 9 | H16: =G16*F16 -> 13491 | I16: {=_xlfn.IFS(G16<5,"No Discount",G16<10,"5-10 Tier Discount",G16>=10,"10+ Tier Discount")} -> 5-10 Tier Discount | J16: =IF(H16>50000,"High",IF(H16<15000,"Medium","Standard")) -> Medium | K16: =VLOOKUP(B16,Lookup_Tables!$A$4:$E$9,3,FALSE) -> SMB Sales | L16: =INDEX(Lookup_Tables!$D$4:$D$9,MATCH(Formulas_Practice!K16,Lookup_Tables!$C$4:$C$9,0)) -> West
... A29: 5026 | B29: SR01 | C29: =VLOOKUP(B29,Lookup_Tables!$A$4:$B$9,2,FALSE) -> Reetu Sharma | D29: Bookshelf | E29: =INDEX(Lookup_Tables!$B$14:$B$43,MATCH(Formulas_Practice!D29,Lookup_Tables!$A$14:$A$43,0)) -> Furniture | F29: =VLOOKUP(D29,Lookup_Tables!$A$13:$C$43,3,FALSE) -> 4999 | G29: 5 | H29: =G29*F29 -> 24995 | I29: {=_xlfn.IFS(G29<5,"No Discount",G29<10,"5-10 Tier Discount",G29>=10,"10+ Tier Discount")} -> 5-10 Tier Discount | J29: =IF(H29>50000,"High",IF(H29<15000,"Medium","Standard")) -> Standard | K29: =VLOOKUP(B29,Lookup_Tables!$A$4:$E$9,3,FALSE) -> Enterprise Sales | L29: =INDEX(Lookup_Tables!$D$4:$D$9,MATCH(Formulas_Practice!K29,Lookup_Tables!$C$4:$C$9,0)) -> North
A32: Formula Hints
A33: • Column C: Look up Rep Full Name from Lookup_Tables!SalesReps using Rep ID.
A34: • Column E: Look up Category from Lookup_Tables!Product Catalog using Product Name.
A35: • Column F: Look up List Price from Lookup_Tables!Product Catalog using Product Name.
A36: • Column H: Quantity × List Price.
A37: • Column I: Nested IF — 'None' if Qty<5, '5% (5-9 units)' if Qty 5-9, '10% (10+ units)' if Qty>=10.
A38: • Column J: IF Line Total > 50000 → 'High Value', elif > 15000 → 'Medium Value', else 'Standard'.
C317: Karan Malhotra

Sheet Answer_Key
A1: Answer Key — Formulas Practice
A2: Same table as Formulas_Practice, with worked formulas. Compare, don't copy first!
A4: Order ID | B4: Rep ID | C4: Rep Full Name (VLOOKUP/XLOOKUP) | D4: Product Name | E4: Category (INDEX-MATCH) | F4: List Price (XLOOKUP) | G4: Quantity | H4: Line Total = Qty×Price | I4: Discount Tier (nested IF) | J4: Order Value Band (IF)
A5: 5002 | B5: SR03 | C5: =VLOOKUP(B5,Lookup_Tables!$A$5:$B$9,2,FALSE()) -> Meera Krishnan | D5: Mechanical Keyboard | E5: =INDEX(Lookup_Tables!$B$14:$B$43,MATCH(D5,Lookup_Tables!$A$14:$A$43,0)) -> Electronics | F5: =INDEX(Lookup_Tables!$C$14:$C$43,MATCH(D5,Lookup_Tables!$A$14:$A$43,0)) -> 2999 | G5: 7 | H5: =G5*F5 -> 20993 | I5: =IF(G5<5,"None",IF(G5<10,"5% (5-9 units)","10% (10+ units)")) -> 5% (5-9 units) | J5: =IF(H5>50000,"High Value",IF(H5>15000,"Medium Value","Standard")) -> Medium Value
A6: 5003 | B6: SR01 | C6: =VLOOKUP(B6,Lookup_Tables!$A$5:$B$9,2,FALSE()) -> Reetu Sharma | D6: 27in Monitor | E6: =INDEX(Lookup_Tables!$B$14:$B$43,MATCH(D6,Lookup_Tables!$A$14:$A$43,0)) -> Electronics | F6: =INDEX(Lookup_Tables!$C$14:$C$43,MATCH(D6,Lookup_Tables!$A$14:$A$43,0)) -> 12999 | G6: 9 | H6: =G6*F6 -> 116991 | I6: =IF(G6<5,"None",IF(G6<10,"5% (5-9 units)","10% (10+ units)")) -> 5% (5-9 units) | J6: =IF(H6>50000,"High Value",IF(H6>15000,"Medium Value","Standard")) -> High Value
A7: 5004 | B7: SR01 | C7: =VLOOKUP(B7,Lookup_Tables!$A$5:$B$9,2,FALSE()) -> Reetu Sharma | D7: Whiteboard Markers | E7: =INDEX(Lookup_Tables!$B$14:$B$43,MATCH(D7,Lookup_Tables!$A$14:$A$43,0)) -> Office Supplies | F7: =INDEX(Lookup_Tables!$C$14:$C$43,MATCH(D7,Lookup_Tables!$A$14:$A$43,0)) -> 199 | G7: 10 | H7: =G7*F7 -> 1990 | I7: =IF(G7<5,"None",IF(G7<10,"5% (5-9 units)","10% (10+ units)")) -> 10% (10+ units) | J7: =IF(H7>50000,"High Value",IF(H7>15000,"Medium Value","Standard")) -> Standard
A8: 5005 | B8: SR01 | C8: =VLOOKUP(B8,Lookup_Tables!$A$5:$B$9,2,FALSE()) -> Reetu Sharma | D8: VPN License | E8: =INDEX(Lookup_Tables!$B$14:$B$43,MATCH(D8,Lookup_Tables!$A$14:$A$43,0)) -> Software | F8: =INDEX(Lookup_Tables!$C$14:$C$43,MATCH(D8,Lookup_Tables!$A$14:$A$43,0)) -> 599 | G8: 9 | H8: =G8*F8 -> 5391 | I8: =IF(G8<5,"None",IF(G8<10,"5% (5-9 units)","10% (10+ units)")) -> 5% (5-9 units) | J8: =IF(H8>50000,"High Value",IF(H8>15000,"Medium Value","Standard")) -> Standard
A9: 5006 | B9: SR02 | C9: =VLOOKUP(B9,Lookup_Tables!$A$5:$B$9,2,FALSE()) -> James Fernandes | D9: USB-C Hub | E9: =INDEX(Lookup_Tables!$B$14:$B$43,MATCH(D9,Lookup_Tables!$A$14:$A$43,0)) -> Electronics | F9: =INDEX(Lookup_Tables!$C$14:$C$43,MATCH(D9,Lookup_Tables!$A$14:$A$43,0)) -> 1499 | G9: 2 | H9: =G9*F9 -> 2998 | I9: =IF(G9<5,"None",IF(G9<10,"5% (5-9 units)","10% (10+ units)")) -> None | J9: =IF(H9>50000,"High Value",IF(H9>15000,"Medium Value","Standard")) -> Standard
A10: 5007 | B10: SR04 | C10: =VLOOKUP(B10,Lookup_Tables!$A$5:$B$9,2,FALSE()) -> Alok Bansal | D10: Ink Cartridge | E10: =INDEX(Lookup_Tables!$B$14:$B$43,MATCH(D10,Lookup_Tables!$A$14:$A$43,0)) -> Office Supplies | F10: =INDEX(Lookup_Tables!$C$14:$C$43,MATCH(D10,Lookup_Tables!$A$14:$A$43,0)) -> 899 | G10: 2 | H10: =G10*F10 -> 1798 | I10: =IF(G10<5,"None",IF(G10<10,"5% (5-9 units)","10% (10+ units)")) -> None | J10: =IF(H10>50000,"High Value",IF(H10>15000,"Medium Value","Standard")) -> Standard
A11: 5008 | B11: SR02 | C11: =VLOOKUP(B11,Lookup_Tables!$A$5:$B$9,2,FALSE()) -> James Fernandes | D11: 27in Monitor | E11: =INDEX(Lookup_Tables!$B$14:$B$43,MATCH(D11,Lookup_Tables!$A$14:$A$43,0)) -> Electronics | F11: =INDEX(Lookup_Tables!$C$14:$C$43,MATCH(D11,Lookup_Tables!$A$14:$A$43,0)) -> 12999 | G11: 9 | H11: =G11*F11 -> 116991 | I11: =IF(G11<5,"None",IF(G11<10,"5% (5-9 units)","10% (10+ units)")) -> 5% (5-9 units) | J11: =IF(H11>50000,"High Value",IF(H11>15000,"Medium Value","Standard")) -> High Value
A12: 5009 | B12: SR04 | C12: =VLOOKUP(B12,Lookup_Tables!$A$5:$B$9,2,FALSE()) -> Alok Bansal | D12: USB-C Hub | E12: =INDEX(Lookup_Tables!$B$14:$B$43,MATCH(D12,Lookup_Tables!$A$14:$A$43,0)) -> Electronics | F12: =INDEX(Lookup_Tables!$C$14:$C$43,MATCH(D12,Lookup_Tables!$A$14:$A$43,0)) -> 1499 | G12: 10 | H12: =G12*F12 -> 14990 | I12: =IF(G12<5,"None",IF(G12<10,"5% (5-9 units)","10% (10+ units)")) -> 10% (10+ units) | J12: =IF(H12>50000,"High Value",IF(H12>15000,"Medium Value","Standard")) -> Standard
A13: 5010 | B13: SR01 | C13: =VLOOKUP(B13,Lookup_Tables!$A$5:$B$9,2,FALSE()) -> Reetu Sharma | D13: Portable SSD 1TB | E13: =INDEX(Lookup_Tables!$B$14:$B$43,MATCH(D13,Lookup_Tables!$A$14:$A$43,0)) -> Electronics | F13: =INDEX(Lookup_Tables!$C$14:$C$43,MATCH(D13,Lookup_Tables!$A$14:$A$43,0)) -> 6499 | G13: 11 | H13: =G13*F13 -> 71489 | I13: =IF(G13<5,"None",IF(G13<10,"5% (5-9 units)","10% (10+ units)")) -> 10% (10+ units) | J13: =IF(H13>50000,"High Value",IF(H13>15000,"Medium Value","Standard")) -> High Value
A14: 5011 | B14: SR05 | C14: =VLOOKUP(B14,Lookup_Tables!$A$5:$B$9,2,FALSE()) -> Farah Khan | D14: USB-C Hub | E14: =INDEX(Lookup_Tables!$B$14:$B$43,MATCH(D14,Lookup_Tables!$A$14:$A$43,0)) -> Electronics | F14: =INDEX(Lookup_Tables!$C$14:$C$43,MATCH(D14,Lookup_Tables!$A$14:$A$43,0)) -> 1499 | G14: 10 | H14: =G14*F14 -> 14990 | I14: =IF(G14<5,"None",IF(G14<10,"5% (5-9 units)","10% (10+ units)")) -> 10% (10+ units) | J14: =IF(H14>50000,"High Value",IF(H14>15000,"Medium Value","Standard")) -> Standard
A15: 5012 | B15: SR05 | C15: =VLOOKUP(B15,Lookup_Tables!$A$5:$B$9,2,FALSE()) -> Farah Khan | D15: Desk Organizer | E15: =INDEX(Lookup_Tables!$B$14:$B$43,MATCH(D15,Lookup_Tables!$A$14:$A$43,0)) -> Office Supplies | F15: =INDEX(Lookup_Tables!$C$14:$C$43,MATCH(D15,Lookup_Tables!$A$14:$A$43,0)) -> 599 | G15: 1 | H15: =G15*F15 -> 599 | I15: =IF(G15<5,"None",IF(G15<10,"5% (5-9 units)","10% (10+ units)")) -> None | J15: =IF(H15>50000,"High Value",IF(H15>15000,"Medium Value","Standard")) -> Standard
A16: 5013 | B16: SR02 | C16: =VLOOKUP(B16,Lookup_Tables!$A$5:$B$9,2,FALSE()) -> James Fernandes | D16: USB-C Hub | E16: =INDEX(Lookup_Tables!$B$14:$B$43,MATCH(D16,Lookup_Tables!$A$14:$A$43,0)) -> Electronics | F16: =INDEX(Lookup_Tables!$C$14:$C$43,MATCH(D16,Lookup_Tables!$A$14:$A$43,0)) -> 1499 | G16: 9 | H16: =G16*F16 -> 13491 | I16: =IF(G16<5,"None",IF(G16<10,"5% (5-9 units)","10% (10+ units)")) -> 5% (5-9 units) | J16: =IF(H16>50000,"High Value",IF(H16>15000,"Medium Value","Standard")) -> Standard
... A29: 5026 | B29: SR01 | C29: =VLOOKUP(B29,Lookup_Tables!$A$5:$B$9,2,FALSE()) -> Reetu Sharma | D29: Bookshelf | E29: =INDEX(Lookup_Tables!$B$14:$B$43,MATCH(D29,Lookup_Tables!$A$14:$A$43,0)) -> Furniture | F29: =INDEX(Lookup_Tables!$C$14:$C$43,MATCH(D29,Lookup_Tables!$A$14:$A$43,0)) -> 4999 | G29: 5 | H29: =G29*F29 -> 24995 | I29: =IF(G29<5,"None",IF(G29<10,"5% (5-9 units)","10% (10+ units)")) -> 5% (5-9 units) | J29: =IF(H29>50000,"High Value",IF(H29>15000,"Medium Value","Standard")) -> Medium Value

Sheet PivotTable_Practice
A1: Pivot Table Practice
A2: Clean dataset below. Select any cell inside it, then Insert > PivotTable, and complete the 5 tasks.
A4: Order ID | B4: Order Date | C4: Customer Name | D4: Region | E4: Product Category | F4: Product Name | G4: Quantity | H4: Unit Price | I4: Discount | J4: Sales Rep | K4: Payment Method | L4: Order Status | M4: Line Total | O4: Pivot Table Tasks
A5: 20002 | B5: 45552 | C5: Horizon Systems | D5: Central | E5: Software | F5: Design Suite License | G5: 8 | H5: 5499 | I5: 0.15 | J5: SR02 | K5: Bank Transfer | L5: Cancelled | M5: =G5*H5*(1-I5) -> 37393.2 | O5: 1. Total Line Total by Region (bar or table).
A6: 20003 | B6: 45520 | C6: Kavya Reddy | D6: South | E6: Software | F6: VPN License | G6: 3 | H6: 599 | I6: 0 | J6: SR01 | K6: Cash | L6: Cancelled | M6: =G6*H6*(1-I6) -> 1797 | O6: 2. Total Line Total by Product Category, broken down by Region (rows=Category, columns=Region).
A7: 20004 | B7: 45611 | C7: Rohan Mehta | D7: Central | E7: Electronics | F7: Noise Cancelling Headphones | G7: 8 | H7: 5999 | I7: 0.05 | J7: SR01 | K7: Credit Card | L7: Completed | M7: =G7*H7*(1-I7) -> 45592.4 | O7: 3. Total Line Total by Month (group Order Date by month).
A8: 20005 | B8: 45459 | C8: Nikhil Chawla | D8: Central | E8: Office Supplies | F8: Whiteboard Markers | G8: 1 | H8: 199 | I8: 0.15 | J8: SR02 | K8: Cash | L8: Completed | M8: =G8*H8*(1-I8) -> 169.15 | O8: 4. Top 5 Customers by total spend (sort descending, filter top 5).
A9: 20006 | B9: 45526 | C9: Global Retail Corp | D9: East | E9: Furniture | F9: Storage Cabinet | G9: 1 | H9: 5499 | I9: 0 | J9: SR04 | K9: Cash | L9: Completed | M9: =G9*H9*(1-I9) -> 5499 | O9: 5. Average Line Total per Sales Rep, plus count of orders per rep.
A10: 20007 | B10: 45307 | C10: Arjun Patel | D10: Central | E10: Furniture | F10: Office Sofa | G10: 4 | H10: 18999 | I10: 0.1 | J10: SR01 | K10: Cheque | L10: Completed | M10: =G10*H10*(1-I10) -> 68396.4
A11: 20008 | B11: 45642 | C11: Rohan Mehta | D11: South | E11: Furniture | F11: Desk Lamp | G11: 2 | H11: 1299 | I11: 0 | J11: SR02 | K11: Credit Card | L11: Pending | M11: =G11*H11*(1-I11) -> 2598
A12: 20009 | B12: 45329 | C12: Amitabh Sinha | D12: South | E12: Software | F12: VPN License | G12: 7 | H12: 599 | I12: 0.15 | J12: SR03 | K12: UPI | L12: Completed | M12: =G12*H12*(1-I12) -> 3564.05
A13: 20010 | B13: 45680 | C13: Neha Verma | D13: South | E13: Furniture | F13: Office Sofa | G13: 1 | H13: 18999 | I13: 0.15 | J13: SR02 | K13: Credit Card | L13: Completed | M13: =G13*H13*(1-I13) -> 16149.15
A14: 20011 | B14: 45641 | C14: Pooja Menon | D14: South | E14: Electronics | F14: Portable SSD 1TB | G14: 8 | H14: 6499 | I14: 0.05 | J14: SR04 | K14: Cash | L14: Completed | M14: =G14*H14*(1-I14) -> 49392.4
A15: 20012 | B15: 45494 | C15: Riya Desai | D15: South | E15: Office Supplies | F15: File Folders Box | G15: 7 | H15: 429 | I15: 0 | J15: SR01 | K15: UPI | L15: Cancelled | M15: =G15*H15*(1-I15) -> 3003
A16: 20013 | B16: 45493 | C16: Horizon Systems | D16: Central | E16: Furniture | F16: Ergonomic Chair | G16: 4 | H16: 8999 | I16: 0.05 | J16: SR05 | K16: Credit Card | L16: Completed | M16: =G16*H16*(1-I16) -> 34196.2
A17: 20014 | B17: 45296 | C17: Apex Manufacturing | D17: Central | E17: Office Supplies | F17: Whiteboard Markers | G17: 8 | H17: 199 | I17: 0.1 | J17: SR03 | K17: UPI | L17: Pending | M17: =G17*H17*(1-I17) -> 1432.8
A18: 20015 | B18: 45590 | C18: Global Retail Corp | D18: South | E18: Electronics | F18: USB-C Hub | G18: 2 | H18: 1499 | I18: 0.05 | J18: SR01 | K18: Cash | L18: Pending | M18: =G18*H18*(1-I18) -> 2848.1
A19: 20016 | B19: 45586 | C19: Karan Malhotra | D19: West | E19: Furniture | F19: Storage Cabinet | G19: 3 | H19: 5499 | I19: 0.15 | J19: SR02 | K19: Bank Transfer | L19: Pending | M19: =G19*H19*(1-I19) -> 14022.45
A20: 20017 | B20: 45670 | C20: Global Retail Corp | D20: Central | E20: Office Supplies | F20: Whiteboard Markers | G20: 4 | H20: 199 | I20: 0.05 | J20: SR02 | K20: Cheque | L20: Pending | M20: =G20*H20*(1-I20) -> 756.2
A21: 20018 | B21: 45347 | C21: Sana Sheikh | D21: Central | E21: Electronics | F21: Noise Cancelling Headphones | G21: 1 | H21: 5999 | I21: 0 | J21: SR03 | K21: Bank Transfer | L21: Cancelled | M21: =G21*H21*(1-I21) -> 5999
... A249: 20246 | B249: 45607 | C249: TechNova Solutions | D249: South | E249: Electronics | F249: 27in Monitor | G249: 6 | H249: 12999 | I249: 0 | J249: SR05 | K249: Cash | L249: Completed | M249: =G249*H249*(1-I249) -> 77994
A250: 20247 | B250: 45380 | C250: Silverline Logistics | D250: North | E250: Software | F250: CRM Subscription | G250: 6 | H250: 3999 | I250: 0 | J250: SR04 | K250: Bank Transfer | L250: Pending | M250: =G250*H250*(1-I250) -> 23994 | O250: Row Labels | P250: Sum of Line Total
A251: 20248 | B251: 45519 | C251: Aditya Kapoor | D251: North | E251: Software | F251: VPN License | G251: 7 | H251: 599 | I251: 0 | J251: SR01 | K251: UPI | L251: Cancelled | M251: =G251*H251*(1-I251) -> 4193 | O251: Central | P251: 1158778.6
A252: 20249 | B252: 45645 | C252: Global Retail Corp | D252: Central | E252: Electronics | F252: USB-C Hub | G252: 7 | H252: 1499 | I252: 0.1 | J252: SR01 | K252: Bank Transfer | L252: Completed | M252: =G252*H252*(1-I252) -> 9443.7 | O252: East | P252: 1229039.8
A253: 20250 | B253: 45371 | C253: Horizon Systems | D253: East | E253: Software | F253: Cloud Storage Plan | G253: 3 | H253: 799 | I253: 0 | J253: SR04 | K253: Cheque | L253: Completed | M253: =G253*H253*(1-I253) -> 2397 | O253: North | P253: 759503.9
A254: 20251 | B254: 45544 | C254: Riya Desai | D254: West | E254: Software | F254: CRM Subscription | G254: 4 | H254: 3999 | I254: 0.15 | J254: SR05 | K254: Cheque | L254: Completed | M254: =G254*H254*(1-I254) -> 13596.6 | O254: South | P254: 1314250.4
A255: 20252 | B255: 45469 | C255: Bluebird Enterprises | D255: South | E255: Office Supplies | F255: Ink Cartridge | G255: 4 | H255: 899 | I255: 0 | J255: SR03 | K255: Cheque | L255: Cancelled | M255: =G255*H255*(1-I255) -> 3596 | O255: West | P255: 1194408.3
A256: 20253 | B256: 45686 | C256: Amitabh Sinha | D256: South | E256: Software | F256: CRM Subscription | G256: 8 | H256: 3999 | I256: 0.1 | J256: SR04 | K256: Cheque | L256: Pending | M256: =G256*H256*(1-I256) -> 28792.8 | O256: Grand Total | P256: 5655981
A257: 20254 | B257: 45471 | C257: Sunrise Traders | D257: West | E257: Electronics | F257: Portable SSD 1TB | G257: 4 | H257: 6499 | I257: 0.1 | J257: SR05 | K257: Credit Card | L257: Pending | M257: =G257*H257*(1-I257) -> 23396.4
A258: 20255 | B258: 45658 | C258: Vivek Rao | D258: West | E258: Electronics | F258: Mechanical Keyboard | G258: 7 | H258: 2999 | I258: 0.05 | J258: SR05 | K258: Credit Card | L258: Cancelled | M258: =G258*H258*(1-I258) -> 19943.35
A259: 20256 | B259: 45541 | C259: Neha Verma | D259: South | E259: Office Supplies | F259: File Folders Box | G259: 8 | H259: 429 | I259: 0.15 | J259: SR02 | K259: Cash | L259: Completed | M259: =G259*H259*(1-I259) -> 2917.2
A260: 20257 | B260: 45582 | C260: Priya Nair | D260: Central | E260: Furniture | F260: Bookshelf | G260: 1 | H260: 4999 | I260: 0.1 | J260: SR04 | K260: UPI | L260: Pending | M260: =G260*H260*(1-I260) -> 4499.1
A261: 20258 | B261: 45342 | C261: Ananya Iyer | D261: South | E261: Office Supplies | F261: Ballpoint Pens Pack | G261: 6 | H261: 99 | I261: 0.1 | J261: SR02 | K261: Bank Transfer | L261: Cancelled | M261: =G261*H261*(1-I261) -> 534.6
A262: 20259 | B262: 45590 | C262: Priya Nair | D262: East | E262: Furniture | F262: Standing Desk | G262: 3 | H262: 15999 | I262: 0.05 | J262: SR03 | K262: UPI | L262: Completed | M262: =G262*H262*(1-I262) -> 45597.15 | O262: Sum of Line Total | P262: Column Labels
A263: 20260 | B263: 45475 | C263: Rohan Mehta | D263: South | E263: Furniture | F263: Conference Table | G263: 2 | H263: 24999 | I263: 0.05 | J263: SR05 | K263: UPI | L263: Cancelled | M263: =G263*H263*(1-I263) -> 47498.1 | O263: Row Labels | P263: Central | Q263: East | R263: North | S263: South | T263: West
A264: 20261 | B264: 45426 | C264: Tanvi Bhatt | D264: North | E264: Furniture | F264: Conference Table | G264: 5 | H264: 24999 | I264: 0.05 | J264: SR03 | K264: Credit Card | L264: Pending | M264: =G264*H264*(1-I264) -> 118745.25 | O264: Electronics | P264: 352600.5 | Q264: 286184.3 | R264: 152333.15 | S264: 306694.25 | T264: 391816.7
O265: Furniture | P265: 634419.7 | Q265: 770728.9 | R265: 467927.4 | S265: 830890.65 | T265: 635157
O266: Office Supplies | P266: 5293.15 | Q266: 20598.2 | R266: 2268.7 | S266: 23803.95 | T266: 34951.2
O267: Software | P267: 166465.3 | Q267: 151528.35 | R267: 136974.65 | S267: 152861.55 | T267: 132483.4
O270: Row Labels | P270: Sum of Line Total
...

Sheet Dashboard_Practice
A1: Dashboard Practice
A2: Uses a monthly + category summary below (pre-aggregated from PivotTable_Practice data). Build 3 charts to form a mini dashboard.
A4: Monthly Sales Summary | D4: Sales by Category | G4: Sales by Region
A5: Month | B5: Total Sales | D5: Category | E5: Total Sales | G5: Region | H5: Total Sales
A6: Jan | B6: 629523 | D6: Electronics | E6: 2897970 | G6: North | H6: 2031399
A7: Feb | B7: 516758 | D7: Office Supplies | E7: 2565703 | G7: South | H7: 1017975
A8: Mar | B8: 767926 | D8: Furniture | E8: 1531731 | G8: East | H8: 1797190
A9: Apr | B9: 877081 | D9: Software | E9: 1872751 | G9: West | H9: 1517756
A10: May | B10: 448711 | G10: Central | H10: 731765
A11: Jun | B11: 393807
A12: Jul | B12: 872025
A13: Aug | B13: 651952
A14: Sep | B14: 625713
A15: Oct | B15: 581058
A16: Nov | B16: 873107
A17: Dec | B17: 947252
A38: Dashboard Tasks
A39: 1. Two starter charts are already placed (monthly trend, category pie). Add a 3rd: Sales by Region as a bar chart (data is in G5:H10).
A40: 2. Reposition/resize charts to form a clean 2x2 or 1-row dashboard layout on this sheet.
A41: 3. Add a title cell 'Sales Performance Dashboard' and light formatting (borders, fill) around the summary tables.
A42: 4. Stretch goal: replace the static Monthly/Category/Region tables with live formulas (SUMIFS) pointing at PivotTable_Practice data.

Sheet Sheet1
T1: Two starter charts are already placed (monthly trend, category pie). Add a 3rd: Sales by Region as a bar chart (data is in G5:H10).
E2: Sales Performance Dashboard | T2: 2. Reposition/resize charts to form a clean 2x2 or 1-row dashboard layout on this sheet.
T3: 3. Add a title cell 'Sales Performance Dashboard' and light formatting (borders, fill) around the summary tables.
Q4: Month | R4: Total Sales | T4: 4. Stretch goal: replace the static Monthly/Category/Region tables with live formulas (SUMIFS) pointing at PivotTable_Practice data.
Q5: Jan | R5: =SUMIFS(PivotTable_Practice!$P$271:$P$282,PivotTable_Practice!$O$271:$O$282,"Jan") -> 1362286.3
Q6: Feb | R6: =SUMIFS(PivotTable_Practice!$P$271:$P$282,PivotTable_Practice!$O$271:$O$282,"Feb") -> 214446
Q7: Mar | R7: =SUMIFS(PivotTable_Practice!$P$271:$P$282,PivotTable_Practice!$O$271:$O$282,"Mar") -> 312145.7
Q8: Apr | R8: =SUMIFS(PivotTable_Practice!$P$271:$P$282,PivotTable_Practice!$O$271:$O$282,"Apr") -> 428664.05
Q9: May | R9: =SUMIFS(PivotTable_Practice!$P$271:$P$282,PivotTable_Practice!$O$271:$O$282,"May") -> 596989.55
Q10: Jun | R10: =SUMIFS(PivotTable_Practice!$P$271:$P$282,PivotTable_Practice!$O$271:$O$282,"Jun") -> 514368.45
Q11: Jul | R11: =SUMIFS(PivotTable_Practice!$P$271:$P$282,PivotTable_Practice!$O$271:$O$282,"Jul") -> 329007.95
Q12: Aug | R12: =SUMIFS(PivotTable_Practice!$P$271:$P$282,PivotTable_Practice!$O$271:$O$282,"Aug") -> 370992.95
Q13: Sep | R13: =SUMIFS(PivotTable_Practice!$P$271:$P$282,PivotTable_Practice!$O$271:$O$282,"Sep") -> 313502.4
Q14: Oct | R14: =SUMIFS(PivotTable_Practice!$P$271:$P$282,PivotTable_Practice!$O$271:$O$282,"Oct") -> 397174.2
Q15: Nov | R15: =SUMIFS(PivotTable_Practice!$P$271:$P$282,PivotTable_Practice!$O$271:$O$282,"Nov") -> 618131.25
Q16: Dec | R16: =SUMIFS(PivotTable_Practice!$P$271:$P$282,PivotTable_Practice!$O$271:$O$282,"Dec") -> 198272.2
Q18: Category | R18: Total Sales
Q19: Electronics | R19: =SUMIFS(PivotTable_Practice!$S$286:$S$289,PivotTable_Practice!$R$286:$R$289,"Electronics") -> 1489628.9
Q20: Office Supplies | R20: =SUMIFS(PivotTable_Practice!$S$286:$S$289,PivotTable_Practice!$R$286:$R$289,"Office Supplies") -> 86915.2
Q21: Furniture | R21: =SUMIFS(PivotTable_Practice!$S$286:$S$289,PivotTable_Practice!$R$286:$R$289,"Furniture") -> 3339123.6
Q22: Software | R22: =SUMIFS(PivotTable_Practice!$S$286:$S$289,PivotTable_Practice!$R$286:$R$289,"Software") -> 740313.25
Q24: Region | R24: Total Sales
Q25: North | R25: =SUMIFS(PivotTable_Practice!$P$251:$P$255,PivotTable_Practice!$O$251:$O$255,"North") -> 759503.9
Q26: South | R26: =SUMIFS(PivotTable_Practice!$P$251:$P$255,PivotTable_Practice!$O$251:$O$255,"South") -> 1314250.4
Q27: East | R27: =SUMIFS(PivotTable_Practice!$P$251:$P$255,PivotTable_Practice!$O$251:$O$255,"East") -> 1229039.8
Q28: West | R28: =SUMIFS(PivotTable_Practice!$P$251:$P$255,PivotTable_Practice!$O$251:$O$255,"West") -> 1194408.3
Q29: Central | R29: =SUMIFS(PivotTable_Practice!$P$251:$P$255,PivotTable_Practice!$O$251:$O$255,"Central") -> 1158778.6
