Workbook
Name Slicer_Department: #N/A
Name Slicer_Employee_status: #N/A

Sheet Instructions
B2: HR Employee Practice Dataset — Data Analyst Exercises
B3: 350+ employee records with realistic HR-data messiness across 3 sheets. Work through the tasks in order.
B5: 1. Data Cleaning
B6: ☐ Split Employee Name into First Name / Last Name — note some are 'Last, First' and some are 'First Last', so a single fixed-position split won't work for all rows. Try TEXTBEFORE/TEXTAFTER logic with LEFT/RIGHT/FIND, or a nested IF that checks for a comma first.
B7: ☐ Standardize Gender to just 'Male' / 'Female' — currently mixed as M/F/male/female/Male/Female.
B8: ☐ Standardize Department using the Lookup_Tables directory (some rows say 'HR', some 'Human Resources', some 'human resources', etc. — all the same department).
B9: ☐ Clean Monthly Salary — strip ₹ and 'Rs.' prefixes and thousands commas, convert everything to a plain number, and decide how to handle blanks.
B10: ☐ Clean Email — trim stray whitespace, and flag/fix addresses missing the '.' in the domain (e.g., '@companycom').
B11: ☐ Clean Phone — some numbers include a +91- prefix, some have a space, some are only 8 digits (incomplete/invalid). Standardize a valid 10-digit format and flag the incomplete ones.
B12: ☐ Fix Leave Balance — some values are negative, which shouldn't be possible. Decide whether to clip to 0 or flag those rows for HR review.
B13: ☐ Remove exact duplicate employee rows.
B15: 2. Core Formulas
... B39: Tip: the Employee Name split is the trickiest part — the two different name formats mean you can't rely on a single FIND position for every row. Test your formula on both formats before dragging it down the whole column.

Sheet HR Dashboard

Sheet Raw_Employee_Data
A1: Employee ID | B1: Employee Name | E1: Gender | F1: Department | G1: Dept Code | H1: manager Name | I1: City | J1: Email | L1: Phone | M1: Phone(remove space) | N1: Phone new | O1: Date of Joining | P1: Date of Exit | S1: Employment Tenure | T1: Tenure | V1: Date of Exit(Year) | W1: Employee status | X1: Monthly Salary | AB1: Performance Rating | AD1: Leave Balance
A2: 5304 | B2: Rajesh Trivedi | C2: =IF(ISNUMBER(SEARCH(",",B2)), TRIM(MID(B2,FIND(",",B2)+1,LEN(B2))&" "&LEFT(B2,FIND(",",B2)-1)), B2) -> Rajesh Trivedi | D2: =PROPER(TRIM(C2)) -> Rajesh Trivedi | E2: Female | F2: Customer Support | G2: D06 | H2: =_xlfn.XLOOKUP(G2,Lookup_Tables!$A$4:$A$9,Lookup_Tables!$C$4:$C$9,"Not Found",0) -> Faisal Ahmed | I2: Mumbai | J2: rajesh.trivedi@company.com | K2: =IF(J2="","No Email ID",SUBSTITUTE(J2,"companycom","company.com")) -> rajesh.trivedi@company.com | M2: =SUBSTITUTE(L2," ","") | N2: {=_xlfn.IFS(M2="","Incomplete",LEN(M2)<10,"Invalid",AND(LEN(M2) =10,LEFT(M2,4) <>"+91-"),"+91-"&M2,TRUE,M2)} -> Incomplete | O2: 2018-08-03 | Q2: =IF(P2="","Missing",P2) -> Missing | R2: {=_xlfn.IFS(OR(Q2="Missing",Q2="N/A",Q2="Still Employed"),Q2,ISNUMBER(SEARCH(",",Q2)),DATEVALUE(Q2),AND(ISNUMBER(SEARCH("-",Q2)),ISNUMBER(VALUE(LEFT(Q2,4)))),DATE(LEFT(Q2,4),MID(Q2,6,2),RIGHT(Q2,2)),ISNUMBER(SEARCH("-",Q2)),DATE(RIGHT(Q2,4),MID(Q2,4,2),LEFT(Q2,2)),ISNUMBER(SEARCH("/",Q2)),DATE(RIGHT(Q2,4),MID(Q2,4,2),LEFT(Q2,2)),TRUE,"Check Manually")} -> Missing | S2: =IF(OR(R2="Missing",R2="N/A",R2="Still Employed"),DATEDIF(O2,TODAY(),"y") &" Years, " &DATEDIF(O2,TODAY(),"ym") & " Months, "&DATEDIF(O2,TODAY(),"md") &" Days",DATEDIF(O2,R2,"y") &" Years, " &DATEDIF(O2,R2,"ym") & " Months, "&DATEDIF(O2,R2,"md") &" Days") -> 7 Years, 11 Months, 18 Days | T2: =VALUE(LEFT(S2,FIND(" Years",S2)-1))*365.25 + VALUE(MID(S2,FIND(", ",S2)+2,FIND(" Months",S2)-FIND(", ",S2)-2))*30.44 + VALUE(MID(S2,FIND("Months, ",S2)+8,FIND(" Days",S2)-FIND("Months, ",S2)-8)) -> 2909.59 | U2: {=_xlfn.IFS(OR(R2="Missing",R2="N/A",R2="Still Employed"),"Unknown",ISNUMBER(R2),"Exited",TRUE,"Unknown")} -> Unknown | V2: =IF(U2="Exited",YEAR(R2),"") | W2: =IF(OR(R2="Missing",R2="N/A",R2="Still Employed"),"Active","Exited") -> Active | X2: ₹159,086 | Y2: =TRIM(X2) -> ₹159,086 | Z2: {=_xlfn.IFS(Y2="","0",LEFT(Y2,5)="",Y2,LEFT(Y2,1)="₹",REPLACE(Y2,1,1,""),LEFT(Y2,4)="Rs. ",REPLACE(Y2,1,4,""),TRUE,Y2)} -> 159,086 | AA2: =SUBSTITUTE(Z2,",","") -> 159086 | AB2: Excellent | AC2: =IF(AB2="","Not Rated",AB2) -> Excellent | AD2: 9 | AE2: {=_xlfn.IFS(AD2="",0,AD2<0,"Negate Leave",AD2>=0,AD2)} -> 9 | AI2: {=_xlfn.UNIQUE(F:F)} -> Department | AJ2: Head Count | AK2: =LEFT(X2,1) -> ₹
A3: 5129 | B3: Pooja Trivedi | C3: =IF(ISNUMBER(SEARCH(",",B3)), TRIM(MID(B3,FIND(",",B3)+1,LEN(B3))&" "&LEFT(B3,FIND(",",B3)-1)), B3) -> Pooja Trivedi | D3: =PROPER(TRIM(C3)) -> Pooja Trivedi | E3: Male | F3: Finance | G3: D05 | H3: =_xlfn.XLOOKUP(G3,Lookup_Tables!$A$4:$A$9,Lookup_Tables!$C$4:$C$9,"Not Found",0) -> Leela Iyer | I3: Kolkata | J3: pooja.trivedi@company.com | K3: =IF(J3="","No Email ID",SUBSTITUTE(J3,"companycom","company.com")) -> pooja.trivedi@company.com | L3: 3302610219 | M3: =SUBSTITUTE(L3," ","") -> 3302610219 | N3: {=_xlfn.IFS(M3="","Incomplete",LEN(M3)<10,"Invalid",AND(LEN(M3) =10,LEFT(M3,4) <>"+91-"),"+91-"&M3,TRUE,M3)} -> +91-3302610219 | O3: 2020-06-18 | Q3: =IF(P3="","Missing",P3) -> Missing | R3: {=_xlfn.IFS(OR(Q3="Missing",Q3="N/A",Q3="Still Employed"),Q3,ISNUMBER(SEARCH(",",Q3)),DATEVALUE(Q3),AND(ISNUMBER(SEARCH("-",Q3)),ISNUMBER(VALUE(LEFT(Q3,4)))),DATE(LEFT(Q3,4),MID(Q3,6,2),RIGHT(Q3,2)),ISNUMBER(SEARCH("-",Q3)),DATE(RIGHT(Q3,4),MID(Q3,4,2),LEFT(Q3,2)),ISNUMBER(SEARCH("/",Q3)),DATE(RIGHT(Q3,4),MID(Q3,4,2),LEFT(Q3,2)),TRUE,"Check Manually")} -> Missing | S3: =IF(OR(R3="Missing",R3="N/A",R3="Still Employed"),DATEDIF(O3,TODAY(),"y") &" Years, " &DATEDIF(O3,TODAY(),"ym") & " Months, "&DATEDIF(O3,TODAY(),"md") &" Days",DATEDIF(O3,R3,"y") &" Years, " &DATEDIF(O3,R3,"ym") & " Months, "&DATEDIF(O3,R3,"md") &" Days") -> 6 Years, 1 Months, 3 Days | T3: =VALUE(LEFT(S3,FIND(" Years",S3)-1))*365.25 + VALUE(MID(S3,FIND(", ",S3)+2,FIND(" Months",S3)-FIND(", ",S3)-2))*30.44 + VALUE(MID(S3,FIND("Months, ",S3)+8,FIND(" Days",S3)-FIND("Months, ",S3)-8)) -> 2224.94 | U3: {=_xlfn.IFS(OR(R3="Missing",R3="N/A",R3="Still Employed"),"Unknown",ISNUMBER(R3),"Exited",TRUE,"Unknown")} -> Unknown | V3: =IF(U3="Exited",YEAR(R3),"") | W3: =IF(OR(R3="Missing",R3="N/A",R3="Still Employed"),"Active","Exited") -> Active | X3: Rs. 89,883 | Y3: =TRIM(X3) -> Rs. 89,883 | Z3: {=_xlfn.IFS(Y3="","0",LEFT(Y3,5)="",Y3,LEFT(Y3,1)="₹",REPLACE(Y3,1,1,""),LEFT(Y3,4)="Rs. ",REPLACE(Y3,1,4,""),TRUE,Y3)} -> 89,883 | AA3: =SUBSTITUTE(Z3,",","") -> 89883 | AC3: =IF(AB3="","Not Rated",AB3) -> Not Rated | AD3: 20 | AE3: {=_xlfn.IFS(AD3="",0,AD3<0,"Negate Leave",AD3>=0,AD3)} -> 20 | AG3: =AVERAGEIF(U2:U344,"Customer Support") -> #DIV/0! | AI3: Customer Support | AJ3: =COUNTIFS($F:$F,"Customer Support") -> 55 | AK3: =LEFT(X3,4) -> Rs.
A4: 5014 | B4: Rajesh Shah | C4: =IF(ISNUMBER(SEARCH(",",B4)), TRIM(MID(B4,FIND(",",B4)+1,LEN(B4))&" "&LEFT(B4,FIND(",",B4)-1)), B4) -> Rajesh Shah | D4: =PROPER(TRIM(C4)) -> Rajesh Shah | E4: Female | F4: Finance | G4: D05 | H4: =_xlfn.XLOOKUP(G4,Lookup_Tables!$A$4:$A$9,Lookup_Tables!$C$4:$C$9,"Not Found",0) -> Leela Iyer | I4: Bengaluru | J4: rajesh.shah@company.com | K4: =IF(J4="","No Email ID",SUBSTITUTE(J4,"companycom","company.com")) -> rajesh.shah@company.com | M4: =SUBSTITUTE(L4," ","") | N4: {=_xlfn.IFS(M4="","Incomplete",LEN(M4)<10,"Invalid",AND(LEN(M4) =10,LEFT(M4,4) <>"+91-"),"+91-"&M4,TRUE,M4)} -> Incomplete | O4: 2019-04-08 | P4: 2024-03-06 | Q4: =IF(P4="","Missing",P4) -> 2024-03-06 | R4: {=_xlfn.IFS(OR(Q4="Missing",Q4="N/A",Q4="Still Employed"),Q4,ISNUMBER(SEARCH(",",Q4)),DATEVALUE(Q4),AND(ISNUMBER(SEARCH("-",Q4)),ISNUMBER(VALUE(LEFT(Q4,4)))),DATE(LEFT(Q4,4),MID(Q4,6,2),RIGHT(Q4,2)),ISNUMBER(SEARCH("-",Q4)),DATE(RIGHT(Q4,4),MID(Q4,4,2),LEFT(Q4,2)),ISNUMBER(SEARCH("/",Q4)),DATE(RIGHT(Q4,4),MID(Q4,4,2),LEFT(Q4,2)),TRUE,"Check Manually")} -> 45357 | S4: =IF(OR(R4="Missing",R4="N/A",R4="Still Employed"),DATEDIF(O4,TODAY(),"y") &" Years, " &DATEDIF(O4,TODAY(),"ym") & " Months, "&DATEDIF(O4,TODAY(),"md") &" Days",DATEDIF(O4,R4,"y") &" Years, " &DATEDIF(O4,R4,"ym") & " Months, "&DATEDIF(O4,R4,"md") &" Days") -> 4 Years, 10 Months, 27 Days | T4: =VALUE(LEFT(S4,FIND(" Years",S4)-1))*365.25 + VALUE(MID(S4,FIND(", ",S4)+2,FIND(" Months",S4)-FIND(", ",S4)-2))*30.44 + VALUE(MID(S4,FIND("Months, ",S4)+8,FIND(" Days",S4)-FIND("Months, ",S4)-8)) -> 1792.4 | U4: {=_xlfn.IFS(OR(R4="Missing",R4="N/A",R4="Still Employed"),"Unknown",ISNUMBER(R4),"Exited",TRUE,"Unknown")} -> Exited | V4: =IF(U4="Exited",YEAR(R4),"") -> 2024 | W4: =IF(OR(R4="Missing",R4="N/A",R4="Still Employed"),"Active","Exited") -> Exited | X4: Rs. 62,467 | Y4: =TRIM(X4) -> Rs. 62,467 | Z4: {=_xlfn.IFS(Y4="","0",LEFT(Y4,5)="",Y4,LEFT(Y4,1)="₹",REPLACE(Y4,1,1,""),LEFT(Y4,4)="Rs. ",REPLACE(Y4,1,4,""),TRUE,Y4)} -> 62,467 | AA4: =SUBSTITUTE(Z4,",","") -> 62467 | AB4: Average | AC4: =IF(AB4="","Not Rated",AB4) -> Average | AD4: 19 | AE4: {=_xlfn.IFS(AD4="",0,AD4<0,"Negate Leave",AD4>=0,AD4)} -> 19 | AI4: Finance | AJ4: =COUNTIFS($F:$F,"Finance") -> 57 | AK4: =LEN(X2) -> 8 | AO4: 44935 | AP4: =MONTH(AO4) -> 1
A5: 5260 | B5: Varun Shah | C5: =IF(ISNUMBER(SEARCH(",",B5)), TRIM(MID(B5,FIND(",",B5)+1,LEN(B5))&" "&LEFT(B5,FIND(",",B5)-1)), B5) -> Varun Shah | D5: =PROPER(TRIM(C5)) -> Varun Shah | E5: Male | F5: Marketing | G5: D04 | H5: =_xlfn.XLOOKUP(G5,Lookup_Tables!$A$4:$A$9,Lookup_Tables!$C$4:$C$9,"Not Found",0) -> Vivek Malhotra | I5: Ahmedabad | J5: varun.shah@company.com | K5: =IF(J5="","No Email ID",SUBSTITUTE(J5,"companycom","company.com")) -> varun.shah@company.com | L5: 72286286 | M5: =SUBSTITUTE(L5," ","") -> 72286286 | N5: {=_xlfn.IFS(M5="","Incomplete",LEN(M5)<10,"Invalid",AND(LEN(M5) =10,LEFT(M5,4) <>"+91-"),"+91-"&M5,TRUE,M5)} -> Invalid | O5: 2023-08-04 | P5: Jun 30, 2025 | Q5: =IF(P5="","Missing",P5) -> Jun 30, 2025 | R5: {=_xlfn.IFS(OR(Q5="Missing",Q5="N/A",Q5="Still Employed"),Q5,ISNUMBER(SEARCH(",",Q5)),DATEVALUE(Q5),AND(ISNUMBER(SEARCH("-",Q5)),ISNUMBER(VALUE(LEFT(Q5,4)))),DATE(LEFT(Q5,4),MID(Q5,6,2),RIGHT(Q5,2)),ISNUMBER(SEARCH("-",Q5)),DATE(RIGHT(Q5,4),MID(Q5,4,2),LEFT(Q5,2)),ISNUMBER(SEARCH("/",Q5)),DATE(RIGHT(Q5,4),MID(Q5,4,2),LEFT(Q5,2)),TRUE,"Check Manually")} -> 45838 | S5: =IF(OR(R5="Missing",R5="N/A",R5="Still Employed"),DATEDIF(O5,TODAY(),"y") &" Years, " &DATEDIF(O5,TODAY(),"ym") & " Months, "&DATEDIF(O5,TODAY(),"md") &" Days",DATEDIF(O5,R5,"y") &" Years, " &DATEDIF(O5,R5,"ym") & " Months, "&DATEDIF(O5,R5,"md") &" Days") -> 1 Years, 10 Months, 26 Days | T5: =VALUE(LEFT(S5,FIND(" Years",S5)-1))*365.25 + VALUE(MID(S5,FIND(", ",S5)+2,FIND(" Months",S5)-FIND(", ",S5)-2))*30.44 + VALUE(MID(S5,FIND("Months, ",S5)+8,FIND(" Days",S5)-FIND("Months, ",S5)-8)) -> 695.65 | U5: {=_xlfn.IFS(OR(R5="Missing",R5="N/A",R5="Still Employed"),"Unknown",ISNUMBER(R5),"Exited",TRUE,"Unknown")} -> Exited | V5: =IF(U5="Exited",YEAR(R5),"") -> 2025 | W5: =IF(OR(R5="Missing",R5="N/A",R5="Still Employed"),"Active","Exited") -> Exited | Y5: =TRIM(X5) | Z5: {=_xlfn.IFS(Y5="","0",LEFT(Y5,5)="",Y5,LEFT(Y5,1)="₹",REPLACE(Y5,1,1,""),LEFT(Y5,4)="Rs. ",REPLACE(Y5,1,4,""),TRUE,Y5)} -> 0 | AA5: =SUBSTITUTE(Z5,",","") -> 0 | AB5: Average | AC5: =IF(AB5="","Not Rated",AB5) -> Average | AD5: 25 | AE5: {=_xlfn.IFS(AD5="",0,AD5<0,"Negate Leave",AD5>=0,AD5)} -> 25 | AG5: 7 years,11months,15 days | AI5: Marketing | AJ5: =COUNTIFS($F:$F,"Marketing") -> 50
A6: 5330 | B6: amit naidu | C6: =IF(ISNUMBER(SEARCH(",",B6)), TRIM(MID(B6,FIND(",",B6)+1,LEN(B6))&" "&LEFT(B6,FIND(",",B6)-1)), B6) -> amit naidu | D6: =PROPER(TRIM(C6)) -> Amit Naidu | E6: Male | F6: Engineering | G6: D01 | H6: =_xlfn.XLOOKUP(G6,Lookup_Tables!$A$4:$A$9,Lookup_Tables!$C$4:$C$9,"Not Found",0) -> Ananya Sen | I6: Pune | J6: amitnaidu@companycom | K6: =IF(J6="","No Email ID",SUBSTITUTE(J6,"companycom","company.com")) -> amitnaidu@company.com | L6: 95044801 | M6: =SUBSTITUTE(L6," ","") -> 95044801 | N6: {=_xlfn.IFS(M6="","Incomplete",LEN(M6)<10,"Invalid",AND(LEN(M6) =10,LEFT(M6,4) <>"+91-"),"+91-"&M6,TRUE,M6)} -> Invalid | O6: 2020-11-29 | P6: 30/04/2025 | Q6: =IF(P6="","Missing",P6) -> 30/04/2025 | R6: {=_xlfn.IFS(OR(Q6="Missing",Q6="N/A",Q6="Still Employed"),Q6,ISNUMBER(SEARCH(",",Q6)),DATEVALUE(Q6),AND(ISNUMBER(SEARCH("-",Q6)),ISNUMBER(VALUE(LEFT(Q6,4)))),DATE(LEFT(Q6,4),MID(Q6,6,2),RIGHT(Q6,2)),ISNUMBER(SEARCH("-",Q6)),DATE(RIGHT(Q6,4),MID(Q6,4,2),LEFT(Q6,2)),ISNUMBER(SEARCH("/",Q6)),DATE(RIGHT(Q6,4),MID(Q6,4,2),LEFT(Q6,2)),TRUE,"Check Manually")} -> 45777 | S6: =IF(OR(R6="Missing",R6="N/A",R6="Still Employed"),DATEDIF(O6,TODAY(),"y") &" Years, " &DATEDIF(O6,TODAY(),"ym") & " Months, "&DATEDIF(O6,TODAY(),"md") &" Days",DATEDIF(O6,R6,"y") &" Years, " &DATEDIF(O6,R6,"ym") & " Months, "&DATEDIF(O6,R6,"md") &" Days") -> 4 Years, 5 Months, 1 Days | T6: =VALUE(LEFT(S6,FIND(" Years",S6)-1))*365.25 + VALUE(MID(S6,FIND(", ",S6)+2,FIND(" Months",S6)-FIND(", ",S6)-2))*30.44 + VALUE(MID(S6,FIND("Months, ",S6)+8,FIND(" Days",S6)-FIND("Months, ",S6)-8)) -> 1614.2 | U6: {=_xlfn.IFS(OR(R6="Missing",R6="N/A",R6="Still Employed"),"Unknown",ISNUMBER(R6),"Exited",TRUE,"Unknown")} -> Exited | V6: =IF(U6="Exited",YEAR(R6),"") -> 2025 | W6: =IF(OR(R6="Missing",R6="N/A",R6="Still Employed"),"Active","Exited") -> Exited | X6: Rs. 162,965 | Y6: =TRIM(X6) -> Rs. 162,965 | Z6: {=_xlfn.IFS(Y6="","0",LEFT(Y6,5)="",Y6,LEFT(Y6,1)="₹",REPLACE(Y6,1,1,""),LEFT(Y6,4)="Rs. ",REPLACE(Y6,1,4,""),TRUE,Y6)} -> 162,965 | AA6: =SUBSTITUTE(Z6,",","") -> 162965 | AB6: Excellent | AC6: =IF(AB6="","Not Rated",AB6) -> Excellent | AD6: 16 | AE6: {=_xlfn.IFS(AD6="",0,AD6<0,"Negate Leave",AD6>=0,AD6)} -> 16 | AI6: Engineering | AJ6: =COUNTIFS($F:$F,"Engineering") -> 62 | AK6: Rs. 89,883 | AL6: =IF(LEFT(AK6,4)=AK3,REPLACE(AK6,1,4,"INR"),"As it is") -> INR89,883 | AO6: 44531 | AP6: =MONTH(AO6) -> 12
A7: 5350 | B7: Arjun Mehta | C7: =IF(ISNUMBER(SEARCH(",",B7)), TRIM(MID(B7,FIND(",",B7)+1,LEN(B7))&" "&LEFT(B7,FIND(",",B7)-1)), B7) -> Arjun Mehta | D7: =PROPER(TRIM(C7)) -> Arjun Mehta | E7: female | F7: Finance | G7: D05 | H7: =_xlfn.XLOOKUP(G7,Lookup_Tables!$A$4:$A$9,Lookup_Tables!$C$4:$C$9,"Not Found",0) -> Leela Iyer | I7: Chennai | J7: arjun.mehta@company.com | K7: =IF(J7="","No Email ID",SUBSTITUTE(J7,"companycom","company.com")) -> arjun.mehta@company.com | L7: 28953756 | M7: =SUBSTITUTE(L7," ","") -> 28953756 | N7: {=_xlfn.IFS(M7="","Incomplete",LEN(M7)<10,"Invalid",AND(LEN(M7) =10,LEFT(M7,4) <>"+91-"),"+91-"&M7,TRUE,M7)} -> Invalid | O7: 2022-09-17 | Q7: =IF(P7="","Missing",P7) -> Missing | R7: {=_xlfn.IFS(OR(Q7="Missing",Q7="N/A",Q7="Still Employed"),Q7,ISNUMBER(SEARCH(",",Q7)),DATEVALUE(Q7),AND(ISNUMBER(SEARCH("-",Q7)),ISNUMBER(VALUE(LEFT(Q7,4)))),DATE(LEFT(Q7,4),MID(Q7,6,2),RIGHT(Q7,2)),ISNUMBER(SEARCH("-",Q7)),DATE(RIGHT(Q7,4),MID(Q7,4,2),LEFT(Q7,2)),ISNUMBER(SEARCH("/",Q7)),DATE(RIGHT(Q7,4),MID(Q7,4,2),LEFT(Q7,2)),TRUE,"Check Manually")} -> Missing | S7: =IF(OR(R7="Missing",R7="N/A",R7="Still Employed"),DATEDIF(O7,TODAY(),"y") &" Years, " &DATEDIF(O7,TODAY(),"ym") & " Months, "&DATEDIF(O7,TODAY(),"md") &" Days",DATEDIF(O7,R7,"y") &" Years, " &DATEDIF(O7,R7,"ym") & " Months, "&DATEDIF(O7,R7,"md") &" Days") -> 3 Years, 10 Months, 4 Days | T7: =VALUE(LEFT(S7,FIND(" Years",S7)-1))*365.25 + VALUE(MID(S7,FIND(", ",S7)+2,FIND(" Months",S7)-FIND(", ",S7)-2))*30.44 + VALUE(MID(S7,FIND("Months, ",S7)+8,FIND(" Days",S7)-FIND("Months, ",S7)-8)) -> 1404.15 | U7: {=_xlfn.IFS(OR(R7="Missing",R7="N/A",R7="Still Employed"),"Unknown",ISNUMBER(R7),"Exited",TRUE,"Unknown")} -> Unknown | V7: =IF(U7="Exited",YEAR(R7),"") | W7: =IF(OR(R7="Missing",R7="N/A",R7="Still Employed"),"Active","Exited") -> Active | X7: 173211 | Y7: =TRIM(X7) -> 173211 | Z7: {=_xlfn.IFS(Y7="","0",LEFT(Y7,5)="",Y7,LEFT(Y7,1)="₹",REPLACE(Y7,1,1,""),LEFT(Y7,4)="Rs. ",REPLACE(Y7,1,4,""),TRUE,Y7)} -> 173211 | AA7: =SUBSTITUTE(Z7,",","") -> 173211 | AB7: Below Average | AC7: =IF(AB7="","Not Rated",AB7) -> Below Average | AD7: 18 | AE7: {=_xlfn.IFS(AD7="",0,AD7<0,"Negate Leave",AD7>=0,AD7)} -> 18 | AI7: Sales | AJ7: =COUNTIFS($F:$F,"Sales") -> 65
A8: 5130 | B8: Priya Kapoor | C8: =IF(ISNUMBER(SEARCH(",",B8)), TRIM(MID(B8,FIND(",",B8)+1,LEN(B8))&" "&LEFT(B8,FIND(",",B8)-1)), B8) -> Priya Kapoor | D8: =PROPER(TRIM(C8)) -> Priya Kapoor | E8: Male | F8: Sales | G8: D02 | H8: =_xlfn.XLOOKUP(G8,Lookup_Tables!$A$4:$A$9,Lookup_Tables!$C$4:$C$9,"Not Found",0) -> Rajiv Kapoor | I8: Bengaluru | J8: priya.kapoor@company.com | K8: =IF(J8="","No Email ID",SUBSTITUTE(J8,"companycom","company.com")) -> priya.kapoor@company.com | L8: 47620 20274 | M8: =SUBSTITUTE(L8," ","") -> 4762020274 | N8: {=_xlfn.IFS(M8="","Incomplete",LEN(M8)<10,"Invalid",AND(LEN(M8) =10,LEFT(M8,4) <>"+91-"),"+91-"&M8,TRUE,M8)} -> +91-4762020274 | O8: 2020-04-27 | Q8: =IF(P8="","Missing",P8) -> Missing | R8: {=_xlfn.IFS(OR(Q8="Missing",Q8="N/A",Q8="Still Employed"),Q8,ISNUMBER(SEARCH(",",Q8)),DATEVALUE(Q8),AND(ISNUMBER(SEARCH("-",Q8)),ISNUMBER(VALUE(LEFT(Q8,4)))),DATE(LEFT(Q8,4),MID(Q8,6,2),RIGHT(Q8,2)),ISNUMBER(SEARCH("-",Q8)),DATE(RIGHT(Q8,4),MID(Q8,4,2),LEFT(Q8,2)),ISNUMBER(SEARCH("/",Q8)),DATE(RIGHT(Q8,4),MID(Q8,4,2),LEFT(Q8,2)),TRUE,"Check Manually")} -> Missing | S8: =IF(OR(R8="Missing",R8="N/A",R8="Still Employed"),DATEDIF(O8,TODAY(),"y") &" Years, " &DATEDIF(O8,TODAY(),"ym") & " Months, "&DATEDIF(O8,TODAY(),"md") &" Days",DATEDIF(O8,R8,"y") &" Years, " &DATEDIF(O8,R8,"ym") & " Months, "&DATEDIF(O8,R8,"md") &" Days") -> 6 Years, 2 Months, 24 Days | T8: =VALUE(LEFT(S8,FIND(" Years",S8)-1))*365.25 + VALUE(MID(S8,FIND(", ",S8)+2,FIND(" Months",S8)-FIND(", ",S8)-2))*30.44 + VALUE(MID(S8,FIND("Months, ",S8)+8,FIND(" Days",S8)-FIND("Months, ",S8)-8)) -> 2276.38 | U8: {=_xlfn.IFS(OR(R8="Missing",R8="N/A",R8="Still Employed"),"Unknown",ISNUMBER(R8),"Exited",TRUE,"Unknown")} -> Unknown | V8: =IF(U8="Exited",YEAR(R8),"") | W8: =IF(OR(R8="Missing",R8="N/A",R8="Still Employed"),"Active","Exited") -> Active | X8: 87855 | Y8: =TRIM(X8) -> 87855 | Z8: {=_xlfn.IFS(Y8="","0",LEFT(Y8,5)="",Y8,LEFT(Y8,1)="₹",REPLACE(Y8,1,1,""),LEFT(Y8,4)="Rs. ",REPLACE(Y8,1,4,""),TRUE,Y8)} -> 87855 | AA8: =SUBSTITUTE(Z8,",","") -> 87855 | AB8: Average | AC8: =IF(AB8="","Not Rated",AB8) -> Average | AD8: 20 | AE8: {=_xlfn.IFS(AD8="",0,AD8<0,"Negate Leave",AD8>=0,AD8)} -> 20 | AI8: HR | AJ8: =COUNTIFS($F:$F,"HR") -> 54 | AO8: =IF(ISNUMBER(SEARCH("-",AO4)),,"NF") -> NF
A9: 5283 | B9: Meenal Pillai | C9: =IF(ISNUMBER(SEARCH(",",B9)), TRIM(MID(B9,FIND(",",B9)+1,LEN(B9))&" "&LEFT(B9,FIND(",",B9)-1)), B9) -> Meenal Pillai | D9: =PROPER(TRIM(C9)) -> Meenal Pillai | E9: Male | F9: Engineering | G9: D01 | H9: =_xlfn.XLOOKUP(G9,Lookup_Tables!$A$4:$A$9,Lookup_Tables!$C$4:$C$9,"Not Found",0) -> Ananya Sen | I9: Ahmedabad | J9: meenal.pillai@company.com | K9: =IF(J9="","No Email ID",SUBSTITUTE(J9,"companycom","company.com")) -> meenal.pillai@company.com | L9: 4819825539 | M9: =SUBSTITUTE(L9," ","") -> 4819825539 | N9: {=_xlfn.IFS(M9="","Incomplete",LEN(M9)<10,"Invalid",AND(LEN(M9) =10,LEFT(M9,4) <>"+91-"),"+91-"&M9,TRUE,M9)} -> +91-4819825539 | O9: 2023-04-20 | P9: Jun 30, 2025 | Q9: =IF(P9="","Missing",P9) -> Jun 30, 2025 | R9: {=_xlfn.IFS(OR(Q9="Missing",Q9="N/A",Q9="Still Employed"),Q9,ISNUMBER(SEARCH(",",Q9)),DATEVALUE(Q9),AND(ISNUMBER(SEARCH("-",Q9)),ISNUMBER(VALUE(LEFT(Q9,4)))),DATE(LEFT(Q9,4),MID(Q9,6,2),RIGHT(Q9,2)),ISNUMBER(SEARCH("-",Q9)),DATE(RIGHT(Q9,4),MID(Q9,4,2),LEFT(Q9,2)),ISNUMBER(SEARCH("/",Q9)),DATE(RIGHT(Q9,4),MID(Q9,4,2),LEFT(Q9,2)),TRUE,"Check Manually")} -> 45838 | S9: =IF(OR(R9="Missing",R9="N/A",R9="Still Employed"),DATEDIF(O9,TODAY(),"y") &" Years, " &DATEDIF(O9,TODAY(),"ym") & " Months, "&DATEDIF(O9,TODAY(),"md") &" Days",DATEDIF(O9,R9,"y") &" Years, " &DATEDIF(O9,R9,"ym") & " Months, "&DATEDIF(O9,R9,"md") &" Days") -> 2 Years, 2 Months, 10 Days | T9: =VALUE(LEFT(S9,FIND(" Years",S9)-1))*365.25 + VALUE(MID(S9,FIND(", ",S9)+2,FIND(" Months",S9)-FIND(", ",S9)-2))*30.44 + VALUE(MID(S9,FIND("Months, ",S9)+8,FIND(" Days",S9)-FIND("Months, ",S9)-8)) -> 801.38 | U9: {=_xlfn.IFS(OR(R9="Missing",R9="N/A",R9="Still Employed"),"Unknown",ISNUMBER(R9),"Exited",TRUE,"Unknown")} -> Exited | V9: =IF(U9="Exited",YEAR(R9),"") -> 2025 | W9: =IF(OR(R9="Missing",R9="N/A",R9="Still Employed"),"Active","Exited") -> Exited | X9: 70870 | Y9: =TRIM(X9) -> 70870 | Z9: {=_xlfn.IFS(Y9="","0",LEFT(Y9,5)="",Y9,LEFT(Y9,1)="₹",REPLACE(Y9,1,1,""),LEFT(Y9,4)="Rs. ",REPLACE(Y9,1,4,""),TRUE,Y9)} -> 70870 | AA9: =SUBSTITUTE(Z9,",","") -> 70870 | AB9: Below Average | AC9: =IF(AB9="","Not Rated",AB9) -> Below Average | AD9: 23 | AE9: {=_xlfn.IFS(AD9="",0,AD9<0,"Negate Leave",AD9>=0,AD9)} -> 23 | AI9: 0 | AJ9: =COUNTIFS($F:$F,"No Dept") -> 0 | AK9: =IF(LEFT(AK6,4)=AK3,REPLACE(AK6,1,4,"INR"),"As it is") -> INR89,883 | AL9: =SUBSTITUTE(AK9,",","") -> INR89883
A10: 5179 | B10: Yash Desai | C10: =IF(ISNUMBER(SEARCH(",",B10)), TRIM(MID(B10,FIND(",",B10)+1,LEN(B10))&" "&LEFT(B10,FIND(",",B10)-1)), B10) -> Yash Desai | D10: =PROPER(TRIM(C10)) -> Yash Desai | E10: Male | F10: Marketing | G10: D04 | H10: =_xlfn.XLOOKUP(G10,Lookup_Tables!$A$4:$A$9,Lookup_Tables!$C$4:$C$9,"Not Found",0) -> Vivek Malhotra | I10: Kolkata | J10: yash.desai@company.com | K10: =IF(J10="","No Email ID",SUBSTITUTE(J10,"companycom","company.com")) -> yash.desai@company.com | L10: +91-4763237185 | M10: =SUBSTITUTE(L10," ","") -> +91-4763237185 | N10: {=_xlfn.IFS(M10="","Incomplete",LEN(M10)<10,"Invalid",AND(LEN(M10) =10,LEFT(M10,4) <>"+91-"),"+91-"&M10,TRUE,M10)} -> +91-4763237185 | O10: 2024-03-10 | Q10: =IF(P10="","Missing",P10) -> Missing | R10: {=_xlfn.IFS(OR(Q10="Missing",Q10="N/A",Q10="Still Employed"),Q10,ISNUMBER(SEARCH(",",Q10)),DATEVALUE(Q10),AND(ISNUMBER(SEARCH("-",Q10)),ISNUMBER(VALUE(LEFT(Q10,4)))),DATE(LEFT(Q10,4),MID(Q10,6,2),RIGHT(Q10,2)),ISNUMBER(SEARCH("-",Q10)),DATE(RIGHT(Q10,4),MID(Q10,4,2),LEFT(Q10,2)),ISNUMBER(SEARCH("/",Q10)),DATE(RIGHT(Q10,4),MID(Q10,4,2),LEFT(Q10,2)),TRUE,"Check Manually")} -> Missing | S10: =IF(OR(R10="Missing",R10="N/A",R10="Still Employed"),DATEDIF(O10,TODAY(),"y") &" Years, " &DATEDIF(O10,TODAY(),"ym") & " Months, "&DATEDIF(O10,TODAY(),"md") &" Days",DATEDIF(O10,R10,"y") &" Years, " &DATEDIF(O10,R10,"ym") & " Months, "&DATEDIF(O10,R10,"md") &" Days") -> 2 Years, 4 Months, 11 Days | T10: =VALUE(LEFT(S10,FIND(" Years",S10)-1))*365.25 + VALUE(MID(S10,FIND(", ",S10)+2,FIND(" Months",S10)-FIND(", ",S10)-2))*30.44 + VALUE(MID(S10,FIND("Months, ",S10)+8,FIND(" Days",S10)-FIND("Months, ",S10)-8)) -> 863.26 | U10: {=_xlfn.IFS(OR(R10="Missing",R10="N/A",R10="Still Employed"),"Unknown",ISNUMBER(R10),"Exited",TRUE,"Unknown")} -> Unknown | V10: =IF(U10="Exited",YEAR(R10),"") | W10: =IF(OR(R10="Missing",R10="N/A",R10="Still Employed"),"Active","Exited") -> Active | X10: 136375 | Y10: =TRIM(X10) -> 136375 | Z10: {=_xlfn.IFS(Y10="","0",LEFT(Y10,5)="",Y10,LEFT(Y10,1)="₹",REPLACE(Y10,1,1,""),LEFT(Y10,4)="Rs. ",REPLACE(Y10,1,4,""),TRUE,Y10)} -> 136375 | AA10: =SUBSTITUTE(Z10,",","") -> 136375 | AC10: =IF(AB10="","Not Rated",AB10) -> Not Rated | AD10: 23 | AE10: {=_xlfn.IFS(AD10="",0,AD10<0,"Negate Leave",AD10>=0,AD10)} -> 23
A11: 5047 | B11: Rohan Kapoor | C11: =IF(ISNUMBER(SEARCH(",",B11)), TRIM(MID(B11,FIND(",",B11)+1,LEN(B11))&" "&LEFT(B11,FIND(",",B11)-1)), B11) -> Rohan Kapoor | D11: =PROPER(TRIM(C11)) -> Rohan Kapoor | E11: Female | F11: Finance | G11: D05 | H11: =_xlfn.XLOOKUP(G11,Lookup_Tables!$A$4:$A$9,Lookup_Tables!$C$4:$C$9,"Not Found",0) -> Leela Iyer | I11: Kolkata | J11: rohankapoor@companycom | K11: =IF(J11="","No Email ID",SUBSTITUTE(J11,"companycom","company.com")) -> rohankapoor@company.com | L11: 4301540486 | M11: =SUBSTITUTE(L11," ","") -> 4301540486 | N11: {=_xlfn.IFS(M11="","Incomplete",LEN(M11)<10,"Invalid",AND(LEN(M11) =10,LEFT(M11,4) <>"+91-"),"+91-"&M11,TRUE,M11)} -> +91-4301540486 | O11: 2022-03-17 | P11: 30/06/2025 | Q11: =IF(P11="","Missing",P11) -> 30/06/2025 | R11: {=_xlfn.IFS(OR(Q11="Missing",Q11="N/A",Q11="Still Employed"),Q11,ISNUMBER(SEARCH(",",Q11)),DATEVALUE(Q11),AND(ISNUMBER(SEARCH("-",Q11)),ISNUMBER(VALUE(LEFT(Q11,4)))),DATE(LEFT(Q11,4),MID(Q11,6,2),RIGHT(Q11,2)),ISNUMBER(SEARCH("-",Q11)),DATE(RIGHT(Q11,4),MID(Q11,4,2),LEFT(Q11,2)),ISNUMBER(SEARCH("/",Q11)),DATE(RIGHT(Q11,4),MID(Q11,4,2),LEFT(Q11,2)),TRUE,"Check Manually")} -> 45838 | S11: =IF(OR(R11="Missing",R11="N/A",R11="Still Employed"),DATEDIF(O11,TODAY(),"y") &" Years, " &DATEDIF(O11,TODAY(),"ym") & " Months, "&DATEDIF(O11,TODAY(),"md") &" Days",DATEDIF(O11,R11,"y") &" Years, " &DATEDIF(O11,R11,"ym") & " Months, "&DATEDIF(O11,R11,"md") &" Days") -> 3 Years, 3 Months, 13 Days | T11: =VALUE(LEFT(S11,FIND(" Years",S11)-1))*365.25 + VALUE(MID(S11,FIND(", ",S11)+2,FIND(" Months",S11)-FIND(", ",S11)-2))*30.44 + VALUE(MID(S11,FIND("Months, ",S11)+8,FIND(" Days",S11)-FIND("Months, ",S11)-8)) -> 1200.07 | U11: {=_xlfn.IFS(OR(R11="Missing",R11="N/A",R11="Still Employed"),"Unknown",ISNUMBER(R11),"Exited",TRUE,"Unknown")} -> Exited | V11: =IF(U11="Exited",YEAR(R11),"") -> 2025 | W11: =IF(OR(R11="Missing",R11="N/A",R11="Still Employed"),"Active","Exited") -> Exited | X11: 56096 | Y11: =TRIM(X11) -> 56096 | Z11: {=_xlfn.IFS(Y11="","0",LEFT(Y11,5)="",Y11,LEFT(Y11,1)="₹",REPLACE(Y11,1,1,""),LEFT(Y11,4)="Rs. ",REPLACE(Y11,1,4,""),TRUE,Y11)} -> 56096 | AA11: =SUBSTITUTE(Z11,",","") -> 56096 | AB11: Average | AC11: =IF(AB11="","Not Rated",AB11) -> Average | AD11: 25 | AE11: {=_xlfn.IFS(AD11="",0,AD11<0,"Negate Leave",AD11>=0,AD11)} -> 25 | AK11: INR | AL11: =LEN(AK11) -> 5
A12: 5316 | B12: Yash Verma | C12: =IF(ISNUMBER(SEARCH(",",B12)), TRIM(MID(B12,FIND(",",B12)+1,LEN(B12))&" "&LEFT(B12,FIND(",",B12)-1)), B12) -> Yash Verma | D12: =PROPER(TRIM(C12)) -> Yash Verma | E12: Female | F12: Finance | G12: D05 | H12: =_xlfn.XLOOKUP(G12,Lookup_Tables!$A$4:$A$9,Lookup_Tables!$C$4:$C$9,"Not Found",0) -> Leela Iyer | I12: Delhi | J12: yash.verma@company.com | K12: =IF(J12="","No Email ID",SUBSTITUTE(J12,"companycom","company.com")) -> yash.verma@company.com | L12: 63588 14765 | M12: =SUBSTITUTE(L12," ","") -> 6358814765 | N12: {=_xlfn.IFS(M12="","Incomplete",LEN(M12)<10,"Invalid",AND(LEN(M12) =10,LEFT(M12,4) <>"+91-"),"+91-"&M12,TRUE,M12)} -> +91-6358814765 | O12: 2021-11-23 | P12: Still Employed | Q12: =IF(P12="","Missing",P12) -> Still Employed | R12: {=_xlfn.IFS(OR(Q12="Missing",Q12="N/A",Q12="Still Employed"),Q12,ISNUMBER(SEARCH(",",Q12)),DATEVALUE(Q12),AND(ISNUMBER(SEARCH("-",Q12)),ISNUMBER(VALUE(LEFT(Q12,4)))),DATE(LEFT(Q12,4),MID(Q12,6,2),RIGHT(Q12,2)),ISNUMBER(SEARCH("-",Q12)),DATE(RIGHT(Q12,4),MID(Q12,4,2),LEFT(Q12,2)),ISNUMBER(SEARCH("/",Q12)),DATE(RIGHT(Q12,4),MID(Q12,4,2),LEFT(Q12,2)),TRUE,"Check Manually")} -> Still Employed | S12: =IF(OR(R12="Missing",R12="N/A",R12="Still Employed"),DATEDIF(O12,TODAY(),"y") &" Years, " &DATEDIF(O12,TODAY(),"ym") & " Months, "&DATEDIF(O12,TODAY(),"md") &" Days",DATEDIF(O12,R12,"y") &" Years, " &DATEDIF(O12,R12,"ym") & " Months, "&DATEDIF(O12,R12,"md") &" Days") -> 4 Years, 7 Months, 28 Days | T12: =VALUE(LEFT(S12,FIND(" Years",S12)-1))*365.25 + VALUE(MID(S12,FIND(", ",S12)+2,FIND(" Months",S12)-FIND(", ",S12)-2))*30.44 + VALUE(MID(S12,FIND("Months, ",S12)+8,FIND(" Days",S12)-FIND("Months, ",S12)-8)) -> 1702.08 | U12: {=_xlfn.IFS(OR(R12="Missing",R12="N/A",R12="Still Employed"),"Unknown",ISNUMBER(R12),"Exited",TRUE,"Unknown")} -> Unknown | V12: =IF(U12="Exited",YEAR(R12),"") | W12: =IF(OR(R12="Missing",R12="N/A",R12="Still Employed"),"Active","Exited") -> Active | X12: ₹130,511 | Y12: =TRIM(X12) -> ₹130,511 | Z12: {=_xlfn.IFS(Y12="","0",LEFT(Y12,5)="",Y12,LEFT(Y12,1)="₹",REPLACE(Y12,1,1,""),LEFT(Y12,4)="Rs. ",REPLACE(Y12,1,4,""),TRUE,Y12)} -> 130,511 | AA12: =SUBSTITUTE(Z12,",","") -> 130511 | AB12: Poor | AC12: =IF(AB12="","Not Rated",AB12) -> Poor | AD12: 16 | AE12: {=_xlfn.IFS(AD12="",0,AD12<0,"Negate Leave",AD12>=0,AD12)} -> 16 | AK12: 173211
A13: 5028 | B13: VIKRAM JOSHI | C13: =IF(ISNUMBER(SEARCH(",",B13)), TRIM(MID(B13,FIND(",",B13)+1,LEN(B13))&" "&LEFT(B13,FIND(",",B13)-1)), B13) -> VIKRAM JOSHI | D13: =PROPER(TRIM(C13)) -> Vikram Joshi | E13: Female | F13: Customer Support | G13: D06 | H13: =_xlfn.XLOOKUP(G13,Lookup_Tables!$A$4:$A$9,Lookup_Tables!$C$4:$C$9,"Not Found",0) -> Faisal Ahmed | I13: Ahmedabad | J13: vikram.joshi@company.com | K13: =IF(J13="","No Email ID",SUBSTITUTE(J13,"companycom","company.com")) -> vikram.joshi@company.com | L13: 0084745378 | M13: =SUBSTITUTE(L13," ","") -> 0084745378 | N13: {=_xlfn.IFS(M13="","Incomplete",LEN(M13)<10,"Invalid",AND(LEN(M13) =10,LEFT(M13,4) <>"+91-"),"+91-"&M13,TRUE,M13)} -> +91-0084745378 | O13: 2019-02-12 | P13: Still Employed | Q13: =IF(P13="","Missing",P13) -> Still Employed | R13: {=_xlfn.IFS(OR(Q13="Missing",Q13="N/A",Q13="Still Employed"),Q13,ISNUMBER(SEARCH(",",Q13)),DATEVALUE(Q13),AND(ISNUMBER(SEARCH("-",Q13)),ISNUMBER(VALUE(LEFT(Q13,4)))),DATE(LEFT(Q13,4),MID(Q13,6,2),RIGHT(Q13,2)),ISNUMBER(SEARCH("-",Q13)),DATE(RIGHT(Q13,4),MID(Q13,4,2),LEFT(Q13,2)),ISNUMBER(SEARCH("/",Q13)),DATE(RIGHT(Q13,4),MID(Q13,4,2),LEFT(Q13,2)),TRUE,"Check Manually")} -> Still Employed | S13: =IF(OR(R13="Missing",R13="N/A",R13="Still Employed"),DATEDIF(O13,TODAY(),"y") &" Years, " &DATEDIF(O13,TODAY(),"ym") & " Months, "&DATEDIF(O13,TODAY(),"md") &" Days",DATEDIF(O13,R13,"y") &" Years, " &DATEDIF(O13,R13,"ym") & " Months, "&DATEDIF(O13,R13,"md") &" Days") -> 7 Years, 5 Months, 9 Days | T13: =VALUE(LEFT(S13,FIND(" Years",S13)-1))*365.25 + VALUE(MID(S13,FIND(", ",S13)+2,FIND(" Months",S13)-FIND(", ",S13)-2))*30.44 + VALUE(MID(S13,FIND("Months, ",S13)+8,FIND(" Days",S13)-FIND("Months, ",S13)-8)) -> 2717.95 | U13: {=_xlfn.IFS(OR(R13="Missing",R13="N/A",R13="Still Employed"),"Unknown",ISNUMBER(R13),"Exited",TRUE,"Unknown")} -> Unknown | V13: =IF(U13="Exited",YEAR(R13),"") | W13: =IF(OR(R13="Missing",R13="N/A",R13="Still Employed"),"Active","Exited") -> Active | X13: ₹85,253 | Y13: =TRIM(X13) -> ₹85,253 | Z13: {=_xlfn.IFS(Y13="","0",LEFT(Y13,5)="",Y13,LEFT(Y13,1)="₹",REPLACE(Y13,1,1,""),LEFT(Y13,4)="Rs. ",REPLACE(Y13,1,4,""),TRUE,Y13)} -> 85,253 | AA13: =SUBSTITUTE(Z13,",","") -> 85253 | AB13: Below Average | AC13: =IF(AB13="","Not Rated",AB13) -> Below Average | AD13: 6 | AE13: {=_xlfn.IFS(AD13="",0,AD13<0,"Negate Leave",AD13>=0,AD13)} -> 6 | AI13: {=_xlfn.UNIQUE(F:F)} -> Department | AJ13: Avg Tenure
A14: 5178 | B14: Saxena, Kirti | C14: =IF(ISNUMBER(SEARCH(",",B14)), TRIM(MID(B14,FIND(",",B14)+1,LEN(B14))&" "&LEFT(B14,FIND(",",B14)-1)), B14) -> Kirti Saxena | D14: =PROPER(TRIM(C14)) -> Kirti Saxena | E14: Female | F14: Sales | G14: D02 | H14: =_xlfn.XLOOKUP(G14,Lookup_Tables!$A$4:$A$9,Lookup_Tables!$C$4:$C$9,"Not Found",0) -> Rajiv Kapoor | I14: Ahmedabad | J14: kirti.saxena@company.com | K14: =IF(J14="","No Email ID",SUBSTITUTE(J14,"companycom","company.com")) -> kirti.saxena@company.com | L14: +91-1004281152 | M14: =SUBSTITUTE(L14," ","") -> +91-1004281152 | N14: {=_xlfn.IFS(M14="","Incomplete",LEN(M14)<10,"Invalid",AND(LEN(M14) =10,LEFT(M14,4) <>"+91-"),"+91-"&M14,TRUE,M14)} -> +91-1004281152 | O14: 2021-05-13 | P14: N/A | Q14: =IF(P14="","Missing",P14) -> N/A | R14: {=_xlfn.IFS(OR(Q14="Missing",Q14="N/A",Q14="Still Employed"),Q14,ISNUMBER(SEARCH(",",Q14)),DATEVALUE(Q14),AND(ISNUMBER(SEARCH("-",Q14)),ISNUMBER(VALUE(LEFT(Q14,4)))),DATE(LEFT(Q14,4),MID(Q14,6,2),RIGHT(Q14,2)),ISNUMBER(SEARCH("-",Q14)),DATE(RIGHT(Q14,4),MID(Q14,4,2),LEFT(Q14,2)),ISNUMBER(SEARCH("/",Q14)),DATE(RIGHT(Q14,4),MID(Q14,4,2),LEFT(Q14,2)),TRUE,"Check Manually")} -> N/A | S14: =IF(OR(R14="Missing",R14="N/A",R14="Still Employed"),DATEDIF(O14,TODAY(),"y") &" Years, " &DATEDIF(O14,TODAY(),"ym") & " Months, "&DATEDIF(O14,TODAY(),"md") &" Days",DATEDIF(O14,R14,"y") &" Years, " &DATEDIF(O14,R14,"ym") & " Months, "&DATEDIF(O14,R14,"md") &" Days") -> 5 Years, 2 Months, 8 Days | T14: =VALUE(LEFT(S14,FIND(" Years",S14)-1))*365.25 + VALUE(MID(S14,FIND(", ",S14)+2,FIND(" Months",S14)-FIND(", ",S14)-2))*30.44 + VALUE(MID(S14,FIND("Months, ",S14)+8,FIND(" Days",S14)-FIND("Months, ",S14)-8)) -> 1895.13 | U14: {=_xlfn.IFS(OR(R14="Missing",R14="N/A",R14="Still Employed"),"Unknown",ISNUMBER(R14),"Exited",TRUE,"Unknown")} -> Unknown | V14: =IF(U14="Exited",YEAR(R14),"") | W14: =IF(OR(R14="Missing",R14="N/A",R14="Still Employed"),"Active","Exited") -> Active | X14: 124338 | Y14: =TRIM(X14) -> 124338 | Z14: {=_xlfn.IFS(Y14="","0",LEFT(Y14,5)="",Y14,LEFT(Y14,1)="₹",REPLACE(Y14,1,1,""),LEFT(Y14,4)="Rs. ",REPLACE(Y14,1,4,""),TRUE,Y14)} -> 124338 | AA14: =SUBSTITUTE(Z14,",","") -> 124338 | AB14: Good | AC14: =IF(AB14="","Not Rated",AB14) -> Good | AD14: 2 | AE14: {=_xlfn.IFS(AD14="",0,AD14<0,"Negate Leave",AD14>=0,AD14)} -> 2 | AI14: Customer Support | AJ14: =AVERAGEIFS(S:S,F:F,"Customer Support") -> #DIV/0! | AK14: Jun 30,2025 | AL14: =TEXT(DATEVALUE(AK14),"DD/MM/YYYY") -> #VALUE!
A15: 5258 | B15: Rao, Tanvi | C15: =IF(ISNUMBER(SEARCH(",",B15)), TRIM(MID(B15,FIND(",",B15)+1,LEN(B15))&" "&LEFT(B15,FIND(",",B15)-1)), B15) -> Tanvi Rao | D15: =PROPER(TRIM(C15)) -> Tanvi Rao | E15: Male | F15: Customer Support | G15: D06 | H15: =_xlfn.XLOOKUP(G15,Lookup_Tables!$A$4:$A$9,Lookup_Tables!$C$4:$C$9,"Not Found",0) -> Faisal Ahmed | I15: Chennai | J15: tanvi.rao@company.com | K15: =IF(J15="","No Email ID",SUBSTITUTE(J15,"companycom","company.com")) -> tanvi.rao@company.com | L15: 80467 74548 | M15: =SUBSTITUTE(L15," ","") -> 8046774548 | N15: {=_xlfn.IFS(M15="","Incomplete",LEN(M15)<10,"Invalid",AND(LEN(M15) =10,LEFT(M15,4) <>"+91-"),"+91-"&M15,TRUE,M15)} -> +91-8046774548 | O15: 2020-02-20 | P15: Still Employed | Q15: =IF(P15="","Missing",P15) -> Still Employed | R15: {=_xlfn.IFS(OR(Q15="Missing",Q15="N/A",Q15="Still Employed"),Q15,ISNUMBER(SEARCH(",",Q15)),DATEVALUE(Q15),AND(ISNUMBER(SEARCH("-",Q15)),ISNUMBER(VALUE(LEFT(Q15,4)))),DATE(LEFT(Q15,4),MID(Q15,6,2),RIGHT(Q15,2)),ISNUMBER(SEARCH("-",Q15)),DATE(RIGHT(Q15,4),MID(Q15,4,2),LEFT(Q15,2)),ISNUMBER(SEARCH("/",Q15)),DATE(RIGHT(Q15,4),MID(Q15,4,2),LEFT(Q15,2)),TRUE,"Check Manually")} -> Still Employed | S15: =IF(OR(R15="Missing",R15="N/A",R15="Still Employed"),DATEDIF(O15,TODAY(),"y") &" Years, " &DATEDIF(O15,TODAY(),"ym") & " Months, "&DATEDIF(O15,TODAY(),"md") &" Days",DATEDIF(O15,R15,"y") &" Years, " &DATEDIF(O15,R15,"ym") & " Months, "&DATEDIF(O15,R15,"md") &" Days") -> 6 Years, 5 Months, 1 Days | T15: =VALUE(LEFT(S15,FIND(" Years",S15)-1))*365.25 + VALUE(MID(S15,FIND(", ",S15)+2,FIND(" Months",S15)-FIND(", ",S15)-2))*30.44 + VALUE(MID(S15,FIND("Months, ",S15)+8,FIND(" Days",S15)-FIND("Months, ",S15)-8)) -> 2344.7 | U15: {=_xlfn.IFS(OR(R15="Missing",R15="N/A",R15="Still Employed"),"Unknown",ISNUMBER(R15),"Exited",TRUE,"Unknown")} -> Unknown | V15: =IF(U15="Exited",YEAR(R15),"") | W15: =IF(OR(R15="Missing",R15="N/A",R15="Still Employed"),"Active","Exited") -> Active | X15: 118204 | Y15: =TRIM(X15) -> 118204 | Z15: {=_xlfn.IFS(Y15="","0",LEFT(Y15,5)="",Y15,LEFT(Y15,1)="₹",REPLACE(Y15,1,1,""),LEFT(Y15,4)="Rs. ",REPLACE(Y15,1,4,""),TRUE,Y15)} -> 118204 | AA15: =SUBSTITUTE(Z15,",","") -> 118204 | AB15: Good | AC15: =IF(AB15="","Not Rated",AB15) -> Good | AD15: 24 | AE15: {=_xlfn.IFS(AD15="",0,AD15<0,"Negate Leave",AD15>=0,AD15)} -> 24 | AI15: Finance
A16: 5325 | B16: Arjun Desai | C16: =IF(ISNUMBER(SEARCH(",",B16)), TRIM(MID(B16,FIND(",",B16)+1,LEN(B16))&" "&LEFT(B16,FIND(",",B16)-1)), B16) -> Arjun Desai | D16: =PROPER(TRIM(C16)) -> Arjun Desai | E16: Male | F16: Marketing | G16: D04 | H16: =_xlfn.XLOOKUP(G16,Lookup_Tables!$A$4:$A$9,Lookup_Tables!$C$4:$C$9,"Not Found",0) -> Vivek Malhotra | I16: Mumbai | J16: arjun.desai@company.com | K16: =IF(J16="","No Email ID",SUBSTITUTE(J16,"companycom","company.com")) -> arjun.desai@company.com | L16: +91-7675703548 | M16: =SUBSTITUTE(L16," ","") -> +91-7675703548 | N16: {=_xlfn.IFS(M16="","Incomplete",LEN(M16)<10,"Invalid",AND(LEN(M16) =10,LEFT(M16,4) <>"+91-"),"+91-"&M16,TRUE,M16)} -> +91-7675703548 | O16: 2022-08-27 | P16: N/A | Q16: =IF(P16="","Missing",P16) -> N/A | R16: {=_xlfn.IFS(OR(Q16="Missing",Q16="N/A",Q16="Still Employed"),Q16,ISNUMBER(SEARCH(",",Q16)),DATEVALUE(Q16),AND(ISNUMBER(SEARCH("-",Q16)),ISNUMBER(VALUE(LEFT(Q16,4)))),DATE(LEFT(Q16,4),MID(Q16,6,2),RIGHT(Q16,2)),ISNUMBER(SEARCH("-",Q16)),DATE(RIGHT(Q16,4),MID(Q16,4,2),LEFT(Q16,2)),ISNUMBER(SEARCH("/",Q16)),DATE(RIGHT(Q16,4),MID(Q16,4,2),LEFT(Q16,2)),TRUE,"Check Manually")} -> N/A | S16: =IF(OR(R16="Missing",R16="N/A",R16="Still Employed"),DATEDIF(O16,TODAY(),"y") &" Years, " &DATEDIF(O16,TODAY(),"ym") & " Months, "&DATEDIF(O16,TODAY(),"md") &" Days",DATEDIF(O16,R16,"y") &" Years, " &DATEDIF(O16,R16,"ym") & " Months, "&DATEDIF(O16,R16,"md") &" Days") -> 3 Years, 10 Months, 24 Days | T16: =VALUE(LEFT(S16,FIND(" Years",S16)-1))*365.25 + VALUE(MID(S16,FIND(", ",S16)+2,FIND(" Months",S16)-FIND(", ",S16)-2))*30.44 + VALUE(MID(S16,FIND("Months, ",S16)+8,FIND(" Days",S16)-FIND("Months, ",S16)-8)) -> 1424.15 | U16: {=_xlfn.IFS(OR(R16="Missing",R16="N/A",R16="Still Employed"),"Unknown",ISNUMBER(R16),"Exited",TRUE,"Unknown")} -> Unknown | V16: =IF(U16="Exited",YEAR(R16),"") | W16: =IF(OR(R16="Missing",R16="N/A",R16="Still Employed"),"Active","Exited") -> Active | X16: ₹137,736 | Y16: =TRIM(X16) -> ₹137,736 | Z16: {=_xlfn.IFS(Y16="","0",LEFT(Y16,5)="",Y16,LEFT(Y16,1)="₹",REPLACE(Y16,1,1,""),LEFT(Y16,4)="Rs. ",REPLACE(Y16,1,4,""),TRUE,Y16)} -> 137,736 | AA16: =SUBSTITUTE(Z16,",","") -> 137736 | AB16: Excellent | AC16: =IF(AB16="","Not Rated",AB16) -> Excellent | AD16: 8 | AE16: {=_xlfn.IFS(AD16="",0,AD16<0,"Negate Leave",AD16>=0,AD16)} -> 8 | AI16: Marketing
A17: 5342 | B17: isha rao | C17: =IF(ISNUMBER(SEARCH(",",B17)), TRIM(MID(B17,FIND(",",B17)+1,LEN(B17))&" "&LEFT(B17,FIND(",",B17)-1)), B17) -> isha rao | D17: =PROPER(TRIM(C17)) -> Isha Rao | E17: Male | F17: HR | G17: D03 | H17: =_xlfn.XLOOKUP(G17,Lookup_Tables!$A$4:$A$9,Lookup_Tables!$C$4:$C$9,"Not Found",0) -> Sunita Rao | I17: Delhi | J17: isha.rao@company.com | K17: =IF(J17="","No Email ID",SUBSTITUTE(J17,"companycom","company.com")) -> isha.rao@company.com | L17: 9742803407 | M17: =SUBSTITUTE(L17," ","") -> 9742803407 | N17: {=_xlfn.IFS(M17="","Incomplete",LEN(M17)<10,"Invalid",AND(LEN(M17) =10,LEFT(M17,4) <>"+91-"),"+91-"&M17,TRUE,M17)} -> +91-9742803407 | O17: 2022-03-24 | Q17: =IF(P17="","Missing",P17) -> Missing | R17: {=_xlfn.IFS(OR(Q17="Missing",Q17="N/A",Q17="Still Employed"),Q17,ISNUMBER(SEARCH(",",Q17)),DATEVALUE(Q17),AND(ISNUMBER(SEARCH("-",Q17)),ISNUMBER(VALUE(LEFT(Q17,4)))),DATE(LEFT(Q17,4),MID(Q17,6,2),RIGHT(Q17,2)),ISNUMBER(SEARCH("-",Q17)),DATE(RIGHT(Q17,4),MID(Q17,4,2),LEFT(Q17,2)),ISNUMBER(SEARCH("/",Q17)),DATE(RIGHT(Q17,4),MID(Q17,4,2),LEFT(Q17,2)),TRUE,"Check Manually")} -> Missing | S17: =IF(OR(R17="Missing",R17="N/A",R17="Still Employed"),DATEDIF(O17,TODAY(),"y") &" Years, " &DATEDIF(O17,TODAY(),"ym") & " Months, "&DATEDIF(O17,TODAY(),"md") &" Days",DATEDIF(O17,R17,"y") &" Years, " &DATEDIF(O17,R17,"ym") & " Months, "&DATEDIF(O17,R17,"md") &" Days") -> 4 Years, 3 Months, 27 Days | T17: =VALUE(LEFT(S17,FIND(" Years",S17)-1))*365.25 + VALUE(MID(S17,FIND(", ",S17)+2,FIND(" Months",S17)-FIND(", ",S17)-2))*30.44 + VALUE(MID(S17,FIND("Months, ",S17)+8,FIND(" Days",S17)-FIND("Months, ",S17)-8)) -> 1579.32 | U17: {=_xlfn.IFS(OR(R17="Missing",R17="N/A",R17="Still Employed"),"Unknown",ISNUMBER(R17),"Exited",TRUE,"Unknown")} -> Unknown | V17: =IF(U17="Exited",YEAR(R17),"") | W17: =IF(OR(R17="Missing",R17="N/A",R17="Still Employed"),"Active","Exited") -> Active | X17: 64962 | Y17: =TRIM(X17) -> 64962 | Z17: {=_xlfn.IFS(Y17="","0",LEFT(Y17,5)="",Y17,LEFT(Y17,1)="₹",REPLACE(Y17,1,1,""),LEFT(Y17,4)="Rs. ",REPLACE(Y17,1,4,""),TRUE,Y17)} -> 64962 | AA17: =SUBSTITUTE(Z17,",","") -> 64962 | AB17: Poor | AC17: =IF(AB17="","Not Rated",AB17) -> Poor | AD17: 22 | AE17: {=_xlfn.IFS(AD17="",0,AD17<0,"Negate Leave",AD17>=0,AD17)} -> 22 | AI17: Engineering | AK17: 30-04-2025 | AL17: =DATEVALUE(AK17) -> #VALUE!
A18: 5185 | B18: Tanvi Menon | C18: =IF(ISNUMBER(SEARCH(",",B18)), TRIM(MID(B18,FIND(",",B18)+1,LEN(B18))&" "&LEFT(B18,FIND(",",B18)-1)), B18) -> Tanvi Menon | D18: =PROPER(TRIM(C18)) -> Tanvi Menon | E18: Male | F18: Customer Support | G18: D06 | H18: =_xlfn.XLOOKUP(G18,Lookup_Tables!$A$4:$A$9,Lookup_Tables!$C$4:$C$9,"Not Found",0) -> Faisal Ahmed | I18: Mumbai | J18: tanvi.menon@company.com | K18: =IF(J18="","No Email ID",SUBSTITUTE(J18,"companycom","company.com")) -> tanvi.menon@company.com | L18: +91-0838728322 | M18: =SUBSTITUTE(L18," ","") -> +91-0838728322 | N18: {=_xlfn.IFS(M18="","Incomplete",LEN(M18)<10,"Invalid",AND(LEN(M18) =10,LEFT(M18,4) <>"+91-"),"+91-"&M18,TRUE,M18)} -> +91-0838728322 | O18: 2018-03-13 | P18: 2021-10-12 | Q18: =IF(P18="","Missing",P18) -> 2021-10-12 | R18: {=_xlfn.IFS(OR(Q18="Missing",Q18="N/A",Q18="Still Employed"),Q18,ISNUMBER(SEARCH(",",Q18)),DATEVALUE(Q18),AND(ISNUMBER(SEARCH("-",Q18)),ISNUMBER(VALUE(LEFT(Q18,4)))),DATE(LEFT(Q18,4),MID(Q18,6,2),RIGHT(Q18,2)),ISNUMBER(SEARCH("-",Q18)),DATE(RIGHT(Q18,4),MID(Q18,4,2),LEFT(Q18,2)),ISNUMBER(SEARCH("/",Q18)),DATE(RIGHT(Q18,4),MID(Q18,4,2),LEFT(Q18,2)),TRUE,"Check Manually")} -> 44481 | S18: =IF(OR(R18="Missing",R18="N/A",R18="Still Employed"),DATEDIF(O18,TODAY(),"y") &" Years, " &DATEDIF(O18,TODAY(),"ym") & " Months, "&DATEDIF(O18,TODAY(),"md") &" Days",DATEDIF(O18,R18,"y") &" Years, " &DATEDIF(O18,R18,"ym") & " Months, "&DATEDIF(O18,R18,"md") &" Days") -> 3 Years, 6 Months, 29 Days | T18: =VALUE(LEFT(S18,FIND(" Years",S18)-1))*365.25 + VALUE(MID(S18,FIND(", ",S18)+2,FIND(" Months",S18)-FIND(", ",S18)-2))*30.44 + VALUE(MID(S18,FIND("Months, ",S18)+8,FIND(" Days",S18)-FIND("Months, ",S18)-8)) -> 1307.39 | U18: {=_xlfn.IFS(OR(R18="Missing",R18="N/A",R18="Still Employed"),"Unknown",ISNUMBER(R18),"Exited",TRUE,"Unknown")} -> Exited | V18: =IF(U18="Exited",YEAR(R18),"") -> 2021 | W18: =IF(OR(R18="Missing",R18="N/A",R18="Still Employed"),"Active","Exited") -> Exited | X18: 129820 | Y18: =TRIM(X18) -> 129820 | Z18: {=_xlfn.IFS(Y18="","0",LEFT(Y18,5)="",Y18,LEFT(Y18,1)="₹",REPLACE(Y18,1,1,""),LEFT(Y18,4)="Rs. ",REPLACE(Y18,1,4,""),TRUE,Y18)} -> 129820 | AA18: =SUBSTITUTE(Z18,",","") -> 129820 | AB18: Good | AC18: =IF(AB18="","Not Rated",AB18) -> Good | AD18: 19 | AE18: {=_xlfn.IFS(AD18="",0,AD18<0,"Negate Leave",AD18>=0,AD18)} -> 19 | AI18: Sales
A19: 5119 | B19: Kavya Naidu | C19: =IF(ISNUMBER(SEARCH(",",B19)), TRIM(MID(B19,FIND(",",B19)+1,LEN(B19))&" "&LEFT(B19,FIND(",",B19)-1)), B19) -> Kavya Naidu | D19: =PROPER(TRIM(C19)) -> Kavya Naidu | E19: Female | F19: Engineering | G19: D01 | H19: =_xlfn.XLOOKUP(G19,Lookup_Tables!$A$4:$A$9,Lookup_Tables!$C$4:$C$9,"Not Found",0) -> Ananya Sen | I19: Bengaluru | J19: kavya.naidu@company.com | K19: =IF(J19="","No Email ID",SUBSTITUTE(J19,"companycom","company.com")) -> kavya.naidu@company.com | L19: 1533142044 | M19: =SUBSTITUTE(L19," ","") -> 1533142044 | N19: {=_xlfn.IFS(M19="","Incomplete",LEN(M19)<10,"Invalid",AND(LEN(M19) =10,LEFT(M19,4) <>"+91-"),"+91-"&M19,TRUE,M19)} -> +91-1533142044 | O19: 2020-01-04 | P19: Still Employed | Q19: =IF(P19="","Missing",P19) -> Still Employed | R19: {=_xlfn.IFS(OR(Q19="Missing",Q19="N/A",Q19="Still Employed"),Q19,ISNUMBER(SEARCH(",",Q19)),DATEVALUE(Q19),AND(ISNUMBER(SEARCH("-",Q19)),ISNUMBER(VALUE(LEFT(Q19,4)))),DATE(LEFT(Q19,4),MID(Q19,6,2),RIGHT(Q19,2)),ISNUMBER(SEARCH("-",Q19)),DATE(RIGHT(Q19,4),MID(Q19,4,2),LEFT(Q19,2)),ISNUMBER(SEARCH("/",Q19)),DATE(RIGHT(Q19,4),MID(Q19,4,2),LEFT(Q19,2)),TRUE,"Check Manually")} -> Still Employed | S19: =IF(OR(R19="Missing",R19="N/A",R19="Still Employed"),DATEDIF(O19,TODAY(),"y") &" Years, " &DATEDIF(O19,TODAY(),"ym") & " Months, "&DATEDIF(O19,TODAY(),"md") &" Days",DATEDIF(O19,R19,"y") &" Years, " &DATEDIF(O19,R19,"ym") & " Months, "&DATEDIF(O19,R19,"md") &" Days") -> 6 Years, 6 Months, 17 Days | T19: =VALUE(LEFT(S19,FIND(" Years",S19)-1))*365.25 + VALUE(MID(S19,FIND(", ",S19)+2,FIND(" Months",S19)-FIND(", ",S19)-2))*30.44 + VALUE(MID(S19,FIND("Months, ",S19)+8,FIND(" Days",S19)-FIND("Months, ",S19)-8)) -> 2391.14 | U19: {=_xlfn.IFS(OR(R19="Missing",R19="N/A",R19="Still Employed"),"Unknown",ISNUMBER(R19),"Exited",TRUE,"Unknown")} -> Unknown | V19: =IF(U19="Exited",YEAR(R19),"") | W19: =IF(OR(R19="Missing",R19="N/A",R19="Still Employed"),"Active","Exited") -> Active | Y19: =TRIM(X19) | Z19: {=_xlfn.IFS(Y19="","0",LEFT(Y19,5)="",Y19,LEFT(Y19,1)="₹",REPLACE(Y19,1,1,""),LEFT(Y19,4)="Rs. ",REPLACE(Y19,1,4,""),TRUE,Y19)} -> 0 | AA19: =SUBSTITUTE(Z19,",","") -> 0 | AC19: =IF(AB19="","Not Rated",AB19) -> Not Rated | AD19: 10 | AE19: {=_xlfn.IFS(AD19="",0,AD19<0,"Negate Leave",AD19>=0,AD19)} -> 10 | AI19: HR | AJ19: 2019-04-08 | AK19: 45357 | AL19: =DAY(AK19) -> 6 | AM19: =MONTH(AK19) -> 3 | AN19: =YEAR(AK19) -> 2024
A20: 5262 | B20: Varun Rao | C20: =IF(ISNUMBER(SEARCH(",",B20)), TRIM(MID(B20,FIND(",",B20)+1,LEN(B20))&" "&LEFT(B20,FIND(",",B20)-1)), B20) -> Varun Rao | D20: =PROPER(TRIM(C20)) -> Varun Rao | E20: Female | F20: Sales | G20: D02 | H20: =_xlfn.XLOOKUP(G20,Lookup_Tables!$A$4:$A$9,Lookup_Tables!$C$4:$C$9,"Not Found",0) -> Rajiv Kapoor | I20: Delhi | J20: varun.rao@company.com | K20: =IF(J20="","No Email ID",SUBSTITUTE(J20,"companycom","company.com")) -> varun.rao@company.com | L20: 4907969025 | M20: =SUBSTITUTE(L20," ","") -> 4907969025 | N20: {=_xlfn.IFS(M20="","Incomplete",LEN(M20)<10,"Invalid",AND(LEN(M20) =10,LEFT(M20,4) <>"+91-"),"+91-"&M20,TRUE,M20)} -> +91-4907969025 | O20: 2019-04-26 | P20: Still Employed | Q20: =IF(P20="","Missing",P20) -> Still Employed | R20: {=_xlfn.IFS(OR(Q20="Missing",Q20="N/A",Q20="Still Employed"),Q20,ISNUMBER(SEARCH(",",Q20)),DATEVALUE(Q20),AND(ISNUMBER(SEARCH("-",Q20)),ISNUMBER(VALUE(LEFT(Q20,4)))),DATE(LEFT(Q20,4),MID(Q20,6,2),RIGHT(Q20,2)),ISNUMBER(SEARCH("-",Q20)),DATE(RIGHT(Q20,4),MID(Q20,4,2),LEFT(Q20,2)),ISNUMBER(SEARCH("/",Q20)),DATE(RIGHT(Q20,4),MID(Q20,4,2),LEFT(Q20,2)),TRUE,"Check Manually")} -> Still Employed | S20: =IF(OR(R20="Missing",R20="N/A",R20="Still Employed"),DATEDIF(O20,TODAY(),"y") &" Years, " &DATEDIF(O20,TODAY(),"ym") & " Months, "&DATEDIF(O20,TODAY(),"md") &" Days",DATEDIF(O20,R20,"y") &" Years, " &DATEDIF(O20,R20,"ym") & " Months, "&DATEDIF(O20,R20,"md") &" Days") -> 7 Years, 2 Months, 25 Days | T20: =VALUE(LEFT(S20,FIND(" Years",S20)-1))*365.25 + VALUE(MID(S20,FIND(", ",S20)+2,FIND(" Months",S20)-FIND(", ",S20)-2))*30.44 + VALUE(MID(S20,FIND("Months, ",S20)+8,FIND(" Days",S20)-FIND("Months, ",S20)-8)) -> 2642.63 | U20: {=_xlfn.IFS(OR(R20="Missing",R20="N/A",R20="Still Employed"),"Unknown",ISNUMBER(R20),"Exited",TRUE,"Unknown")} -> Unknown | V20: =IF(U20="Exited",YEAR(R20),"") | W20: =IF(OR(R20="Missing",R20="N/A",R20="Still Employed"),"Active","Exited") -> Active | X20: Rs. 171,338 | Y20: =TRIM(X20) -> Rs. 171,338 | Z20: {=_xlfn.IFS(Y20="","0",LEFT(Y20,5)="",Y20,LEFT(Y20,1)="₹",REPLACE(Y20,1,1,""),LEFT(Y20,4)="Rs. ",REPLACE(Y20,1,4,""),TRUE,Y20)} -> 171,338 | AA20: =SUBSTITUTE(Z20,",","") -> 171338 | AB20: Below Average | AC20: =IF(AB20="","Not Rated",AB20) -> Below Average | AD20: 13 | AE20: {=_xlfn.IFS(AD20="",0,AD20<0,"Negate Leave",AD20>=0,AD20)} -> 13 | AI20: 0
A21: 5033 | B21: Reddy, Deepak | C21: =IF(ISNUMBER(SEARCH(",",B21)), TRIM(MID(B21,FIND(",",B21)+1,LEN(B21))&" "&LEFT(B21,FIND(",",B21)-1)), B21) -> Deepak Reddy | D21: =PROPER(TRIM(C21)) -> Deepak Reddy | E21: Female | F21: Engineering | G21: D01 | H21: =_xlfn.XLOOKUP(G21,Lookup_Tables!$A$4:$A$9,Lookup_Tables!$C$4:$C$9,"Not Found",0) -> Ananya Sen | I21: Kolkata | J21: deepakreddy@companycom | K21: =IF(J21="","No Email ID",SUBSTITUTE(J21,"companycom","company.com")) -> deepakreddy@company.com | L21: 4293557591 | M21: =SUBSTITUTE(L21," ","") -> 4293557591 | N21: {=_xlfn.IFS(M21="","Incomplete",LEN(M21)<10,"Invalid",AND(LEN(M21) =10,LEFT(M21,4) <>"+91-"),"+91-"&M21,TRUE,M21)} -> +91-4293557591 | O21: 2020-10-25 | P21: 30/06/2025 | Q21: =IF(P21="","Missing",P21) -> 30/06/2025 | R21: {=_xlfn.IFS(OR(Q21="Missing",Q21="N/A",Q21="Still Employed"),Q21,ISNUMBER(SEARCH(",",Q21)),DATEVALUE(Q21),AND(ISNUMBER(SEARCH("-",Q21)),ISNUMBER(VALUE(LEFT(Q21,4)))),DATE(LEFT(Q21,4),MID(Q21,6,2),RIGHT(Q21,2)),ISNUMBER(SEARCH("-",Q21)),DATE(RIGHT(Q21,4),MID(Q21,4,2),LEFT(Q21,2)),ISNUMBER(SEARCH("/",Q21)),DATE(RIGHT(Q21,4),MID(Q21,4,2),LEFT(Q21,2)),TRUE,"Check Manually")} -> 45838 | S21: =IF(OR(R21="Missing",R21="N/A",R21="Still Employed"),DATEDIF(O21,TODAY(),"y") &" Years, " &DATEDIF(O21,TODAY(),"ym") & " Months, "&DATEDIF(O21,TODAY(),"md") &" Days",DATEDIF(O21,R21,"y") &" Years, " &DATEDIF(O21,R21,"ym") & " Months, "&DATEDIF(O21,R21,"md") &" Days") -> 4 Years, 8 Months, 5 Days | T21: =VALUE(LEFT(S21,FIND(" Years",S21)-1))*365.25 + VALUE(MID(S21,FIND(", ",S21)+2,FIND(" Months",S21)-FIND(", ",S21)-2))*30.44 + VALUE(MID(S21,FIND("Months, ",S21)+8,FIND(" Days",S21)-FIND("Months, ",S21)-8)) -> 1709.52 | U21: {=_xlfn.IFS(OR(R21="Missing",R21="N/A",R21="Still Employed"),"Unknown",ISNUMBER(R21),"Exited",TRUE,"Unknown")} -> Exited | V21: =IF(U21="Exited",YEAR(R21),"") -> 2025 | W21: =IF(OR(R21="Missing",R21="N/A",R21="Still Employed"),"Active","Exited") -> Exited | X21: 69,788 | Y21: =TRIM(X21) -> 69,788 | Z21: {=_xlfn.IFS(Y21="","0",LEFT(Y21,5)="",Y21,LEFT(Y21,1)="₹",REPLACE(Y21,1,1,""),LEFT(Y21,4)="Rs. ",REPLACE(Y21,1,4,""),TRUE,Y21)} -> 69,788 | AA21: =SUBSTITUTE(Z21,",","") -> 69788 | AB21: Good | AC21: =IF(AB21="","Not Rated",AB21) -> Good | AD21: -1 | AE21: {=_xlfn.IFS(AD21="",0,AD21<0,"Negate Leave",AD21>=0,AD21)} -> Negate Leave | AK21: =AK19-AJ19 -> 1794 | AL21: =_xlfn.DAYS(AK19,AJ19) -> 1794
A22: 5187 | B22: Kirti Iyer | C22: =IF(ISNUMBER(SEARCH(",",B22)), TRIM(MID(B22,FIND(",",B22)+1,LEN(B22))&" "&LEFT(B22,FIND(",",B22)-1)), B22) -> Kirti Iyer | D22: =PROPER(TRIM(C22)) -> Kirti Iyer | E22: Female | F22: Marketing | G22: D04 | H22: =_xlfn.XLOOKUP(G22,Lookup_Tables!$A$4:$A$9,Lookup_Tables!$C$4:$C$9,"Not Found",0) -> Vivek Malhotra | I22: Chennai | J22: kirti.iyer@company.com | K22: =IF(J22="","No Email ID",SUBSTITUTE(J22,"companycom","company.com")) -> kirti.iyer@company.com | L22: 3326596442 | M22: =SUBSTITUTE(L22," ","") -> 3326596442 | N22: {=_xlfn.IFS(M22="","Incomplete",LEN(M22)<10,"Invalid",AND(LEN(M22) =10,LEFT(M22,4) <>"+91-"),"+91-"&M22,TRUE,M22)} -> +91-3326596442 | O22: 2021-08-03 | P22: Still Employed | Q22: =IF(P22="","Missing",P22) -> Still Employed | R22: {=_xlfn.IFS(OR(Q22="Missing",Q22="N/A",Q22="Still Employed"),Q22,ISNUMBER(SEARCH(",",Q22)),DATEVALUE(Q22),AND(ISNUMBER(SEARCH("-",Q22)),ISNUMBER(VALUE(LEFT(Q22,4)))),DATE(LEFT(Q22,4),MID(Q22,6,2),RIGHT(Q22,2)),ISNUMBER(SEARCH("-",Q22)),DATE(RIGHT(Q22,4),MID(Q22,4,2),LEFT(Q22,2)),ISNUMBER(SEARCH("/",Q22)),DATE(RIGHT(Q22,4),MID(Q22,4,2),LEFT(Q22,2)),TRUE,"Check Manually")} -> Still Employed | S22: =IF(OR(R22="Missing",R22="N/A",R22="Still Employed"),DATEDIF(O22,TODAY(),"y") &" Years, " &DATEDIF(O22,TODAY(),"ym") & " Months, "&DATEDIF(O22,TODAY(),"md") &" Days",DATEDIF(O22,R22,"y") &" Years, " &DATEDIF(O22,R22,"ym") & " Months, "&DATEDIF(O22,R22,"md") &" Days") -> 4 Years, 11 Months, 18 Days | T22: =VALUE(LEFT(S22,FIND(" Years",S22)-1))*365.25 + VALUE(MID(S22,FIND(", ",S22)+2,FIND(" Months",S22)-FIND(", ",S22)-2))*30.44 + VALUE(MID(S22,FIND("Months, ",S22)+8,FIND(" Days",S22)-FIND("Months, ",S22)-8)) -> 1813.84 | U22: {=_xlfn.IFS(OR(R22="Missing",R22="N/A",R22="Still Employed"),"Unknown",ISNUMBER(R22),"Exited",TRUE,"Unknown")} -> Unknown | V22: =IF(U22="Exited",YEAR(R22),"") | W22: =IF(OR(R22="Missing",R22="N/A",R22="Still Employed"),"Active","Exited") -> Active | X22: 177349 | Y22: =TRIM(X22) -> 177349 | Z22: {=_xlfn.IFS(Y22="","0",LEFT(Y22,5)="",Y22,LEFT(Y22,1)="₹",REPLACE(Y22,1,1,""),LEFT(Y22,4)="Rs. ",REPLACE(Y22,1,4,""),TRUE,Y22)} -> 177349 | AA22: =SUBSTITUTE(Z22,",","") -> 177349 | AB22: Good | AC22: =IF(AB22="","Not Rated",AB22) -> Good | AD22: 7 | AE22: {=_xlfn.IFS(AD22="",0,AD22<0,"Negate Leave",AD22>=0,AD22)} -> 7 | AL22: =DATEDIF(0,AL21,"y") -> 4
A23: 5234 | B23: Manish Trivedi | C23: =IF(ISNUMBER(SEARCH(",",B23)), TRIM(MID(B23,FIND(",",B23)+1,LEN(B23))&" "&LEFT(B23,FIND(",",B23)-1)), B23) -> Manish Trivedi | D23: =PROPER(TRIM(C23)) -> Manish Trivedi | E23: Female | F23: Customer Support | G23: D06 | H23: =_xlfn.XLOOKUP(G23,Lookup_Tables!$A$4:$A$9,Lookup_Tables!$C$4:$C$9,"Not Found",0) -> Faisal Ahmed | I23: Mumbai | J23: manish.trivedi@company.com | K23: =IF(J23="","No Email ID",SUBSTITUTE(J23,"companycom","company.com")) -> manish.trivedi@company.com | L23: +91-1825477549 | M23: =SUBSTITUTE(L23," ","") -> +91-1825477549 | N23: {=_xlfn.IFS(M23="","Incomplete",LEN(M23)<10,"Invalid",AND(LEN(M23) =10,LEFT(M23,4) <>"+91-"),"+91-"&M23,TRUE,M23)} -> +91-1825477549 | O23: 2022-05-19 | P23: 30/06/2025 | Q23: =IF(P23="","Missing",P23) -> 30/06/2025 | R23: {=_xlfn.IFS(OR(Q23="Missing",Q23="N/A",Q23="Still Employed"),Q23,ISNUMBER(SEARCH(",",Q23)),DATEVALUE(Q23),AND(ISNUMBER(SEARCH("-",Q23)),ISNUMBER(VALUE(LEFT(Q23,4)))),DATE(LEFT(Q23,4),MID(Q23,6,2),RIGHT(Q23,2)),ISNUMBER(SEARCH("-",Q23)),DATE(RIGHT(Q23,4),MID(Q23,4,2),LEFT(Q23,2)),ISNUMBER(SEARCH("/",Q23)),DATE(RIGHT(Q23,4),MID(Q23,4,2),LEFT(Q23,2)),TRUE,"Check Manually")} -> 45838 | S23: =IF(OR(R23="Missing",R23="N/A",R23="Still Employed"),DATEDIF(O23,TODAY(),"y") &" Years, " &DATEDIF(O23,TODAY(),"ym") & " Months, "&DATEDIF(O23,TODAY(),"md") &" Days",DATEDIF(O23,R23,"y") &" Years, " &DATEDIF(O23,R23,"ym") & " Months, "&DATEDIF(O23,R23,"md") &" Days") -> 3 Years, 1 Months, 11 Days | T23: =VALUE(LEFT(S23,FIND(" Years",S23)-1))*365.25 + VALUE(MID(S23,FIND(", ",S23)+2,FIND(" Months",S23)-FIND(", ",S23)-2))*30.44 + VALUE(MID(S23,FIND("Months, ",S23)+8,FIND(" Days",S23)-FIND("Months, ",S23)-8)) -> 1137.19 | U23: {=_xlfn.IFS(OR(R23="Missing",R23="N/A",R23="Still Employed"),"Unknown",ISNUMBER(R23),"Exited",TRUE,"Unknown")} -> Exited | V23: =IF(U23="Exited",YEAR(R23),"") -> 2025 | W23: =IF(OR(R23="Missing",R23="N/A",R23="Still Employed"),"Active","Exited") -> Exited | X23: Rs. 157,049 | Y23: =TRIM(X23) -> Rs. 157,049 | Z23: {=_xlfn.IFS(Y23="","0",LEFT(Y23,5)="",Y23,LEFT(Y23,1)="₹",REPLACE(Y23,1,1,""),LEFT(Y23,4)="Rs. ",REPLACE(Y23,1,4,""),TRUE,Y23)} -> 157,049 | AA23: =SUBSTITUTE(Z23,",","") -> 157049 | AB23: Below Average | AC23: =IF(AB23="","Not Rated",AB23) -> Below Average | AD23: 18 | AE23: {=_xlfn.IFS(AD23="",0,AD23<0,"Negate Leave",AD23>=0,AD23)} -> 18 | AI23: IFERROR(AVERAGEIFS($D$2:$D$296, $B$2:$B$296, H2), 0) | AL23: =DATEDIF(0,AL21,"ym") -> 10
A24: 5257 | B24: Naidu, Kavya | C24: =IF(ISNUMBER(SEARCH(",",B24)), TRIM(MID(B24,FIND(",",B24)+1,LEN(B24))&" "&LEFT(B24,FIND(",",B24)-1)), B24) -> Kavya Naidu | D24: =PROPER(TRIM(C24)) -> Kavya Naidu | E24: Male | F24: HR | G24: D03 | H24: =_xlfn.XLOOKUP(G24,Lookup_Tables!$A$4:$A$9,Lookup_Tables!$C$4:$C$9,"Not Found",0) -> Sunita Rao | I24: Hyderabad | J24: kavya.naidu@company.com | K24: =IF(J24="","No Email ID",SUBSTITUTE(J24,"companycom","company.com")) -> kavya.naidu@company.com | L24: 7175635077 | M24: =SUBSTITUTE(L24," ","") -> 7175635077 | N24: {=_xlfn.IFS(M24="","Incomplete",LEN(M24)<10,"Invalid",AND(LEN(M24) =10,LEFT(M24,4) <>"+91-"),"+91-"&M24,TRUE,M24)} -> +91-7175635077 | O24: 2023-10-19 | P24: N/A | Q24: =IF(P24="","Missing",P24) -> N/A | R24: {=_xlfn.IFS(OR(Q24="Missing",Q24="N/A",Q24="Still Employed"),Q24,ISNUMBER(SEARCH(",",Q24)),DATEVALUE(Q24),AND(ISNUMBER(SEARCH("-",Q24)),ISNUMBER(VALUE(LEFT(Q24,4)))),DATE(LEFT(Q24,4),MID(Q24,6,2),RIGHT(Q24,2)),ISNUMBER(SEARCH("-",Q24)),DATE(RIGHT(Q24,4),MID(Q24,4,2),LEFT(Q24,2)),ISNUMBER(SEARCH("/",Q24)),DATE(RIGHT(Q24,4),MID(Q24,4,2),LEFT(Q24,2)),TRUE,"Check Manually")} -> N/A | S24: =IF(OR(R24="Missing",R24="N/A",R24="Still Employed"),DATEDIF(O24,TODAY(),"y") &" Years, " &DATEDIF(O24,TODAY(),"ym") & " Months, "&DATEDIF(O24,TODAY(),"md") &" Days",DATEDIF(O24,R24,"y") &" Years, " &DATEDIF(O24,R24,"ym") & " Months, "&DATEDIF(O24,R24,"md") &" Days") -> 2 Years, 9 Months, 2 Days | T24: =VALUE(LEFT(S24,FIND(" Years",S24)-1))*365.25 + VALUE(MID(S24,FIND(", ",S24)+2,FIND(" Months",S24)-FIND(", ",S24)-2))*30.44 + VALUE(MID(S24,FIND("Months, ",S24)+8,FIND(" Days",S24)-FIND("Months, ",S24)-8)) -> 1006.46 | U24: {=_xlfn.IFS(OR(R24="Missing",R24="N/A",R24="Still Employed"),"Unknown",ISNUMBER(R24),"Exited",TRUE,"Unknown")} -> Unknown | V24: =IF(U24="Exited",YEAR(R24),"") | W24: =IF(OR(R24="Missing",R24="N/A",R24="Still Employed"),"Active","Exited") -> Active | X24: ₹68,179 | Y24: =TRIM(X24) -> ₹68,179 | Z24: {=_xlfn.IFS(Y24="","0",LEFT(Y24,5)="",Y24,LEFT(Y24,1)="₹",REPLACE(Y24,1,1,""),LEFT(Y24,4)="Rs. ",REPLACE(Y24,1,4,""),TRUE,Y24)} -> 68,179 | AA24: =SUBSTITUTE(Z24,",","") -> 68179 | AB24: Poor | AC24: =IF(AB24="","Not Rated",AB24) -> Poor | AD24: 11 | AE24: {=_xlfn.IFS(AD24="",0,AD24<0,"Negate Leave",AD24>=0,AD24)} -> 11 | AL24: =DATEDIF(0,AL21,"md") -> 28
A25: 5222 | B25: Anita Trivedi | C25: =IF(ISNUMBER(SEARCH(",",B25)), TRIM(MID(B25,FIND(",",B25)+1,LEN(B25))&" "&LEFT(B25,FIND(",",B25)-1)), B25) -> Anita Trivedi | D25: =PROPER(TRIM(C25)) -> Anita Trivedi | E25: Male | F25: Customer Support | G25: D06 | H25: =_xlfn.XLOOKUP(G25,Lookup_Tables!$A$4:$A$9,Lookup_Tables!$C$4:$C$9,"Not Found",0) -> Faisal Ahmed | I25: Ahmedabad | J25: anita.trivedi@company.com | K25: =IF(J25="","No Email ID",SUBSTITUTE(J25,"companycom","company.com")) -> anita.trivedi@company.com | L25: 5604428899 | M25: =SUBSTITUTE(L25," ","") -> 5604428899 | N25: {=_xlfn.IFS(M25="","Incomplete",LEN(M25)<10,"Invalid",AND(LEN(M25) =10,LEFT(M25,4) <>"+91-"),"+91-"&M25,TRUE,M25)} -> +91-5604428899 | O25: 2021-02-04 | Q25: =IF(P25="","Missing",P25) -> Missing | R25: {=_xlfn.IFS(OR(Q25="Missing",Q25="N/A",Q25="Still Employed"),Q25,ISNUMBER(SEARCH(",",Q25)),DATEVALUE(Q25),AND(ISNUMBER(SEARCH("-",Q25)),ISNUMBER(VALUE(LEFT(Q25,4)))),DATE(LEFT(Q25,4),MID(Q25,6,2),RIGHT(Q25,2)),ISNUMBER(SEARCH("-",Q25)),DATE(RIGHT(Q25,4),MID(Q25,4,2),LEFT(Q25,2)),ISNUMBER(SEARCH("/",Q25)),DATE(RIGHT(Q25,4),MID(Q25,4,2),LEFT(Q25,2)),TRUE,"Check Manually")} -> Missing | S25: =IF(OR(R25="Missing",R25="N/A",R25="Still Employed"),DATEDIF(O25,TODAY(),"y") &" Years, " &DATEDIF(O25,TODAY(),"ym") & " Months, "&DATEDIF(O25,TODAY(),"md") &" Days",DATEDIF(O25,R25,"y") &" Years, " &DATEDIF(O25,R25,"ym") & " Months, "&DATEDIF(O25,R25,"md") &" Days") -> 5 Years, 5 Months, 17 Days | T25: =VALUE(LEFT(S25,FIND(" Years",S25)-1))*365.25 + VALUE(MID(S25,FIND(", ",S25)+2,FIND(" Months",S25)-FIND(", ",S25)-2))*30.44 + VALUE(MID(S25,FIND("Months, ",S25)+8,FIND(" Days",S25)-FIND("Months, ",S25)-8)) -> 1995.45 | U25: {=_xlfn.IFS(OR(R25="Missing",R25="N/A",R25="Still Employed"),"Unknown",ISNUMBER(R25),"Exited",TRUE,"Unknown")} -> Unknown | V25: =IF(U25="Exited",YEAR(R25),"") | W25: =IF(OR(R25="Missing",R25="N/A",R25="Still Employed"),"Active","Exited") -> Active | X25: 108898 | Y25: =TRIM(X25) -> 108898 | Z25: {=_xlfn.IFS(Y25="","0",LEFT(Y25,5)="",Y25,LEFT(Y25,1)="₹",REPLACE(Y25,1,1,""),LEFT(Y25,4)="Rs. ",REPLACE(Y25,1,4,""),TRUE,Y25)} -> 108898 | AA25: =SUBSTITUTE(Z25,",","") -> 108898 | AB25: Good | AC25: =IF(AB25="","Not Rated",AB25) -> Good | AD25: 24 | AE25: {=_xlfn.IFS(AD25="",0,AD25<0,"Negate Leave",AD25>=0,AD25)} -> 24
